<sdf version='1.6'>
  <world name='default'>
    <light name='sun' type='directional'>
      <cast_shadows>1</cast_shadows>
      <pose frame=''>0 0 10 0 -0 0</pose>
      <diffuse>0.8 0.8 0.8 1</diffuse>
      <specular>0.2 0.2 0.2 1</specular>
      <attenuation>
        <range>1000</range>
        <constant>0.9</constant>
        <linear>0.01</linear>
        <quadratic>0.001</quadratic>
      </attenuation>
      <direction>-0.5 0.1 -0.9</direction>
    </light>
    <model name='ground_plane'>
      <static>1</static>
      <link name='link'>
        <collision name='collision'>
          <geometry>
            <plane>
              <normal>0 0 1</normal>
              <size>100 100</size>
            </plane>
          </geometry>
          <surface>
            <friction>
              <ode>
                <mu>100</mu>
                <mu2>50</mu2>
              </ode>
              <torsional>
                <ode/>
              </torsional>
            </friction>
            <contact>
              <ode/>
            </contact>
            <bounce/>
          </surface>
          <max_contacts>10</max_contacts>
        </collision>
        <visual name='visual'>
          <cast_shadows>0</cast_shadows>
          <geometry>
            <plane>
              <normal>0 0 1</normal>
              <size>100 100</size>
            </plane>
          </geometry>
          <material>
            <script>
              <uri>file://media/materials/scripts/gazebo.material</uri>
              <name>Gazebo/Grey</name>
            </script>
          </material>
        </visual>
        <self_collide>0</self_collide>
        <kinematic>0</kinematic>
      </link>
    </model>
    <gravity>0 0 -9.8</gravity>
    <magnetic_field>6e-06 2.3e-05 -4.2e-05</magnetic_field>
    <atmosphere type='adiabatic'/>
    <physics name='default_physics' default='0' type='ode'>
      <max_step_size>0.001</max_step_size>
      <real_time_factor>1</real_time_factor>
      <real_time_update_rate>1000</real_time_update_rate>
    </physics>
    <scene>
      <ambient>0.4 0.4 0.4 1</ambient>
      <background>0.7 0.7 0.7 1</background>
      <shadows>1</shadows>
    </scene>
    <spherical_coordinates>
      <surface_model>EARTH_WGS84</surface_model>
      <latitude_deg>0</latitude_deg>
      <longitude_deg>0</longitude_deg>
      <elevation>0</elevation>
      <heading_deg>0</heading_deg>
    </spherical_coordinates>
    <model name='mantra_with_oil_gun'>
      <link name='base_link'>
        <pose frame=''>0 0 0 0 -0 0</pose>
        <inertial>
          <pose frame=''>0 -0 0.053478 0 -0 0</pose>
          <mass>500</mass>
          <inertia>
            <ixx>3.00001</ixx>
            <ixy>6.6e-06</ixy>
            <ixz>-7.62348e-06</ixz>
            <iyy>3.00003</iyy>
            <iyz>-3.20869e-07</iyz>
            <izz>3.00003</izz>
          </inertia>
        </inertial>
        <collision name='base_link_collision'>
          <pose frame=''>0 0 0 0 -0 0</pose>
          <geometry>
            <mesh>
              <scale>1 1 1</scale>
              <uri>/home/sdhm/catkin_ws/src/mantra_robot/mantra_with_oil_gun_description/meshes/base_link.STL</uri>
            </mesh>
          </geometry>
          <max_contacts>10</max_contacts>
          <surface>
            <contact>
              <ode/>
            </contact>
            <bounce/>
            <friction>
              <torsional>
                <ode/>
              </torsional>
              <ode/>
            </friction>
          </surface>
        </collision>
        <collision name='base_link_fixed_joint_lump__background_link_collision_1'>
          <pose frame=''>1.1 -0.6 0 0 -0 1.5708</pose>
          <geometry>
            <mesh>
              <scale>1 1 1</scale>
              <uri>/home/sdhm/catkin_ws/src/mantra_robot/mantra_with_oil_gun_gazebo/meshes/background.STL</uri>
            </mesh>
          </geometry>
          <surface>
            <contact>
              <ode/>
            </contact>
            <friction>
              <ode/>
              <torsional>
                <ode/>
              </torsional>
            </friction>
            <bounce/>
          </surface>
          <max_contacts>10</max_contacts>
        </collision>
        <collision name='base_link_fixed_joint_lump__oil_filler_link_collision_2'>
          <pose frame=''>1.1 0 0.8 1.57077 -1.57079 2.3e-05</pose>
          <geometry>
            <mesh>
              <scale>1 1 1</scale>
              <uri>/home/sdhm/catkin_ws/src/mantra_robot/mantra_with_oil_gun_gazebo/meshes/oil_filler.STL</uri>
            </mesh>
          </geometry>
          <surface>
            <contact>
              <ode/>
            </contact>
            <friction>
              <ode/>
              <torsional>
                <ode/>
              </torsional>
            </friction>
            <bounce/>
          </surface>
          <max_contacts>10</max_contacts>
        </collision>
        <visual name='base_link_visual'>
          <pose frame=''>0 0 0 0 -0 0</pose>
          <geometry>
            <mesh>
              <scale>1 1 1</scale>
              <uri>/home/sdhm/catkin_ws/src/mantra_robot/mantra_with_oil_gun_description/meshes/base_link.STL</uri>
            </mesh>
          </geometry>
        </visual>
        <visual name='base_link_fixed_joint_lump__background_link_visual_1'>
          <pose frame=''>1.1 -0.6 0 0 -0 1.5708</pose>
          <geometry>
            <mesh>
              <scale>1 1 1</scale>
              <uri>/home/sdhm/catkin_ws/src/mantra_robot/mantra_with_oil_gun_gazebo/meshes/background.STL</uri>
            </mesh>
          </geometry>
          <material>
            <script>
              <name>Gazebo/Grey</name>
              <uri>file://media/materials/scripts/gazebo.material</uri>
            </script>
          </material>
        </visual>
        <visual name='base_link_fixed_joint_lump__oil_filler_link_visual_2'>
          <pose frame=''>1.1 0 0.8 1.57077 -1.57079 2.3e-05</pose>
          <geometry>
            <mesh>
              <scale>1 1 1</scale>
              <uri>/home/sdhm/catkin_ws/src/mantra_robot/mantra_with_oil_gun_gazebo/meshes/oil_filler.STL</uri>
            </mesh>
          </geometry>
          <material>
            <script>
              <name>Gazebo/WhiteGlow</name>
              <uri>file://media/materials/scripts/gazebo.material</uri>
            </script>
          </material>
        </visual>
        <velocity_decay/>
        <gravity>1</gravity>
        <velocity_decay/>
        <self_collide>0</self_collide>
        <kinematic>0</kinematic>
      </link>
      <link name='link1'>
        <pose frame=''>0 0 0.2005 0 -0 0</pose>
        <inertial>
          <pose frame=''>3e-06 0.037673 0.113955 0 -0 0</pose>
          <mass>0.449846</mass>
          <inertia>
            <ixx>0.00281542</ixx>
            <ixy>-2.97928e-08</ixy>
            <ixz>2.31552e-09</ixz>
            <iyy>0.00237879</iyy>
            <iyz>-0.000689611</iyz>
            <izz>0.00161667</izz>
          </inertia>
        </inertial>
        <collision name='link1_collision'>
          <pose frame=''>0 0 0 0 -0 0</pose>
          <geometry>
            <mesh>
              <scale>1 1 1</scale>
              <uri>/home/sdhm/catkin_ws/src/mantra_robot/mantra_with_oil_gun_description/meshes/link1.STL</uri>
            </mesh>
          </geometry>
          <max_contacts>10</max_contacts>
          <surface>
            <contact>
              <ode/>
            </contact>
            <bounce/>
            <friction>
              <torsional>
                <ode/>
              </torsional>
              <ode/>
            </friction>
          </surface>
        </collision>
        <visual name='link1_visual'>
          <pose frame=''>0 0 0 0 -0 0</pose>
          <geometry>
            <mesh>
              <scale>1 1 1</scale>
              <uri>/home/sdhm/catkin_ws/src/mantra_robot/mantra_with_oil_gun_description/meshes/link1.STL</uri>
            </mesh>
          </geometry>
        </visual>
        <self_collide>0</self_collide>
        <kinematic>0</kinematic>
      </link>
      <joint name='joint1' type='revolute'>
        <child>link1</child>
        <parent>base_link</parent>
        <axis>
          <xyz>0 0 -1</xyz>
          <limit>
            <lower>-1.5708</lower>
            <upper>1.5708</upper>
            <effort>100</effort>
            <velocity>1</velocity>
          </limit>
          <dynamics>
            <spring_reference>0</spring_reference>
            <spring_stiffness>0</spring_stiffness>
          </dynamics>
          <use_parent_model_frame>1</use_parent_model_frame>
        </axis>
      </joint>
      <link name='link2'>
        <pose frame=''>0 0 0.3705 1.5708 -0 0</pose>
        <inertial>
          <pose frame=''>3e-06 0.056045 0.037673 0 -0 0</pose>
          <mass>0.449846</mass>
          <inertia>
            <ixx>0.00281542</ixx>
            <ixy>-2.31552e-09</ixy>
            <ixz>-2.97928e-08</ixz>
            <iyy>0.00161667</iyy>
            <iyz>0.000689611</iyz>
            <izz>0.00237879</izz>
          </inertia>
        </inertial>
        <collision name='link2_collision'>
          <pose frame=''>0 0 0 0 -0 0</pose>
          <geometry>
            <mesh>
              <scale>1 1 1</scale>
              <uri>/home/sdhm/catkin_ws/src/mantra_robot/mantra_with_oil_gun_description/meshes/link2.STL</uri>
            </mesh>
          </geometry>
          <max_contacts>10</max_contacts>
          <surface>
            <contact>
              <ode/>
            </contact>
            <bounce/>
            <friction>
              <torsional>
                <ode/>
              </torsional>
              <ode/>
            </friction>
          </surface>
        </collision>
        <visual name='link2_visual'>
          <pose frame=''>0 0 0 0 -0 0</pose>
          <geometry>
            <mesh>
              <scale>1 1 1</scale>
              <uri>/home/sdhm/catkin_ws/src/mantra_robot/mantra_with_oil_gun_description/meshes/link2.STL</uri>
            </mesh>
          </geometry>
        </visual>
        <self_collide>0</self_collide>
        <kinematic>0</kinematic>
      </link>
      <joint name='joint2' type='revolute'>
        <child>link2</child>
        <parent>link1</parent>
        <axis>
          <xyz>0 1 4e-06</xyz>
          <limit>
            <lower>-1.85</lower>
            <upper>1.85</upper>
            <effort>100</effort>
            <velocity>1</velocity>
          </limit>
          <dynamics>
            <spring_reference>0</spring_reference>
            <spring_stiffness>0</spring_stiffness>
          </dynamics>
          <use_parent_model_frame>1</use_parent_model_frame>
        </axis>
      </joint>
      <link name='link3'>
        <pose frame=''>0 -1e-06 0.5405 0 -0 0</pose>
        <inertial>
          <pose frame=''>-7e-06 0.030029 0.103546 0 -0 0</pose>
          <mass>0.392582</mass>
          <inertia>
            <ixx>0.00207552</ixx>
            <ixy>1.3934e-08</ixy>
            <ixz>-2.85481e-08</ixz>
            <iyy>0.00178702</iyy>
            <iyz>-0.000503156</iyz>
            <izz>0.00121405</izz>
          </inertia>
        </inertial>
        <collision name='link3_collision'>
          <pose frame=''>0 0 0 0 -0 0</pose>
          <geometry>
            <mesh>
              <scale>1 1 1</scale>
              <uri>/home/sdhm/catkin_ws/src/mantra_robot/mantra_with_oil_gun_description/meshes/link3.STL</uri>
            </mesh>
          </geometry>
          <max_contacts>10</max_contacts>
          <surface>
            <contact>
              <ode/>
            </contact>
            <bounce/>
            <friction>
              <torsional>
                <ode/>
              </torsional>
              <ode/>
            </friction>
          </surface>
        </collision>
        <visual name='link3_visual'>
          <pose frame=''>0 0 0 0 -0 0</pose>
          <geometry>
            <mesh>
              <scale>1 1 1</scale>
              <uri>/home/sdhm/catkin_ws/src/mantra_robot/mantra_with_oil_gun_description/meshes/link3.STL</uri>
            </mesh>
          </geometry>
        </visual>
        <self_collide>0</self_collide>
        <kinematic>0</kinematic>
      </link>
      <joint name='joint3' type='revolute'>
        <child>link3</child>
        <parent>link2</parent>
        <axis>
          <xyz>0 0 -1</xyz>
          <limit>
            <lower>-1.5708</lower>
            <upper>1.5708</upper>
            <effort>100</effort>
            <velocity>1</velocity>
          </limit>
          <dynamics>
            <spring_reference>0</spring_reference>
            <spring_stiffness>0</spring_stiffness>
          </dynamics>
          <use_parent_model_frame>1</use_parent_model_frame>
        </axis>
      </joint>
      <link name='link4'>
        <pose frame=''>0 -1e-06 0.7005 1.5708 -0 0</pose>
        <inertial>
          <pose frame=''>1e-06 0.053967 0.031711 0 -0 0</pose>
          <mass>0.367226</mass>
          <inertia>
            <ixx>0.00189945</ixx>
            <ixy>1.10762e-08</ixy>
            <ixz>-3.75708e-09</ixz>
            <iyy>0.00102605</iyy>
            <iyz>0.000467411</iyz>
            <izz>0.00163165</izz>
          </inertia>
        </inertial>
        <collision name='link4_collision'>
          <pose frame=''>0 0 0 0 -0 0</pose>
          <geometry>
            <mesh>
              <scale>1 1 1</scale>
              <uri>/home/sdhm/catkin_ws/src/mantra_robot/mantra_with_oil_gun_description/meshes/link4.STL</uri>
            </mesh>
          </geometry>
          <max_contacts>10</max_contacts>
          <surface>
            <contact>
              <ode/>
            </contact>
            <bounce/>
            <friction>
              <torsional>
                <ode/>
              </torsional>
              <ode/>
            </friction>
          </surface>
        </collision>
        <visual name='link4_visual'>
          <pose frame=''>0 0 0 0 -0 0</pose>
          <geometry>
            <mesh>
              <scale>1 1 1</scale>
              <uri>/home/sdhm/catkin_ws/src/mantra_robot/mantra_with_oil_gun_description/meshes/link4.STL</uri>
            </mesh>
          </geometry>
        </visual>
        <self_collide>0</self_collide>
        <kinematic>0</kinematic>
      </link>
      <joint name='joint4' type='revolute'>
        <child>link4</child>
        <parent>link3</parent>
        <axis>
          <xyz>0 1 4e-06</xyz>
          <limit>
            <lower>-1.85</lower>
            <upper>1.85</upper>
            <effort>100</effort>
            <velocity>1</velocity>
          </limit>
          <dynamics>
            <spring_reference>0</spring_reference>
            <spring_stiffness>0</spring_stiffness>
          </dynamics>
          <use_parent_model_frame>1</use_parent_model_frame>
        </axis>
      </joint>
      <link name='link5'>
        <pose frame=''>0 -1e-06 0.8605 0 -0 0</pose>
        <inertial>
          <pose frame=''>1e-06 0.031711 0.106033 0 -0 0</pose>
          <mass>0.367226</mass>
          <inertia>
            <ixx>0.00189945</ixx>
            <ixy>-3.75975e-09</ixy>
            <ixz>-1.10613e-08</ixz>
            <iyy>0.00163165</iyy>
            <iyz>-0.000467411</iyz>
            <izz>0.00102605</izz>
          </inertia>
        </inertial>
        <collision name='link5_collision'>
          <pose frame=''>0 0 0 0 -0 0</pose>
          <geometry>
            <mesh>
              <scale>1 1 1</scale>
              <uri>/home/sdhm/catkin_ws/src/mantra_robot/mantra_with_oil_gun_description/meshes/link5.STL</uri>
            </mesh>
          </geometry>
          <max_contacts>10</max_contacts>
          <surface>
            <contact>
              <ode/>
            </contact>
            <bounce/>
            <friction>
              <torsional>
                <ode/>
              </torsional>
              <ode/>
            </friction>
          </surface>
        </collision>
        <visual name='link5_visual'>
          <pose frame=''>0 0 0 0 -0 0</pose>
          <geometry>
            <mesh>
              <scale>1 1 1</scale>
              <uri>/home/sdhm/catkin_ws/src/mantra_robot/mantra_with_oil_gun_description/meshes/link5.STL</uri>
            </mesh>
          </geometry>
        </visual>
        <self_collide>0</self_collide>
        <kinematic>0</kinematic>
      </link>
      <joint name='joint5' type='revolute'>
        <child>link5</child>
        <parent>link4</parent>
        <axis>
          <xyz>0 0 -1</xyz>
          <limit>
            <lower>-1.5708</lower>
            <upper>1.5708</upper>
            <effort>100</effort>
            <velocity>1</velocity>
          </limit>
          <dynamics>
            <spring_reference>0</spring_reference>
            <spring_stiffness>0</spring_stiffness>
          </dynamics>
          <use_parent_model_frame>1</use_parent_model_frame>
        </axis>
      </joint>
      <link name='link6'>
        <pose frame=''>0 -1e-06 1.0205 1.5708 -0 0</pose>
        <inertial>
          <pose frame=''>1e-06 0.053967 0.031711 0 -0 0</pose>
          <mass>0.367226</mass>
          <inertia>
            <ixx>0.00189945</ixx>
            <ixy>1.1088e-08</ixy>
            <ixz>-3.81501e-09</ixz>
            <iyy>0.00102605</iyy>
            <iyz>0.000467411</iyz>
            <izz>0.00163165</izz>
          </inertia>
        </inertial>
        <collision name='link6_collision'>
          <pose frame=''>0 0 0 0 -0 0</pose>
          <geometry>
            <mesh>
              <scale>1 1 1</scale>
              <uri>/home/sdhm/catkin_ws/src/mantra_robot/mantra_with_oil_gun_description/meshes/link6.STL</uri>
            </mesh>
          </geometry>
          <max_contacts>10</max_contacts>
          <surface>
            <contact>
              <ode/>
            </contact>
            <bounce/>
            <friction>
              <torsional>
                <ode/>
              </torsional>
              <ode/>
            </friction>
          </surface>
        </collision>
        <visual name='link6_visual'>
          <pose frame=''>0 0 0 0 -0 0</pose>
          <geometry>
            <mesh>
              <scale>1 1 1</scale>
              <uri>/home/sdhm/catkin_ws/src/mantra_robot/mantra_with_oil_gun_description/meshes/link6.STL</uri>
            </mesh>
          </geometry>
        </visual>
        <self_collide>0</self_collide>
        <kinematic>0</kinematic>
      </link>
      <joint name='joint6' type='revolute'>
        <child>link6</child>
        <parent>link5</parent>
        <axis>
          <xyz>0 1 4e-06</xyz>
          <limit>
            <lower>-1.85</lower>
            <upper>1.85</upper>
            <effort>100</effort>
            <velocity>1</velocity>
          </limit>
          <dynamics>
            <spring_reference>0</spring_reference>
            <spring_stiffness>0</spring_stiffness>
          </dynamics>
          <use_parent_model_frame>1</use_parent_model_frame>
        </axis>
      </joint>
      <link name='link7'>
        <pose frame=''>0 -2e-06 1.246 0 -0 0</pose>
        <inertial>
          <pose frame=''>-7e-06 -1.1e-05 -0.025003 0 -0 0</pose>
          <mass>0.140448</mass>
          <inertia>
            <ixx>1.00017</ixx>
            <ixy>1.10409e-11</ixy>
            <ixz>5.00281e-09</ixz>
            <iyy>1.00017</iyy>
            <iyz>2.7872e-08</iyz>
            <izz>1.00023</izz>
          </inertia>
        </inertial>
        <collision name='link7_collision'>
          <pose frame=''>0 0 0 0 -0 0</pose>
          <geometry>
            <mesh>
              <scale>1 1 1</scale>
              <uri>/home/sdhm/catkin_ws/src/mantra_robot/mantra_with_oil_gun_description/meshes/link7.STL</uri>
            </mesh>
          </geometry>
          <max_contacts>10</max_contacts>
          <surface>
            <contact>
              <ode/>
            </contact>
            <bounce/>
            <friction>
              <torsional>
                <ode/>
              </torsional>
              <ode/>
            </friction>
          </surface>
        </collision>
        <collision name='link7_fixed_joint_lump__camera_link_collision_1'>
          <pose frame=''>-0.1 0 -0.02 1.5708 -0 1.5708</pose>
          <geometry>
            <mesh>
              <scale>1 1 1</scale>
              <uri>/home/sdhm/catkin_ws/src/mantra_robot/mantra_with_oil_gun_gazebo/meshes/d435.STL</uri>
            </mesh>
          </geometry>
          <surface>
            <contact>
              <ode/>
            </contact>
            <friction>
              <ode/>
              <torsional>
                <ode/>
              </torsional>
            </friction>
            <bounce/>
          </surface>
          <max_contacts>10</max_contacts>
        </collision>
        <visual name='link7_visual'>
          <pose frame=''>0 0 0 0 -0 0</pose>
          <geometry>
            <mesh>
              <scale>1 1 1</scale>
              <uri>/home/sdhm/catkin_ws/src/mantra_robot/mantra_with_oil_gun_description/meshes/link7.STL</uri>
            </mesh>
          </geometry>
        </visual>
        <visual name='link7_fixed_joint_lump__camera_link_visual_1'>
          <pose frame=''>-0.1 0 -0.02 1.5708 -0 1.5708</pose>
          <geometry>
            <mesh>
              <scale>1 1 1</scale>
              <uri>/home/sdhm/catkin_ws/src/mantra_robot/mantra_with_oil_gun_gazebo/meshes/d435.STL</uri>
            </mesh>
          </geometry>
          <material>
            <script>
              <uri>__default__</uri>
              <name>__default__</name>
            </script>
          </material>
        </visual>
        <gravity>1</gravity>
        <velocity_decay/>
        <sensor name='camera' type='camera'>
          <update_rate>30</update_rate>
          <camera name='d435i'>
            <horizontal_fov>1.3</horizontal_fov>
            <image>
              <width>640</width>
              <height>480</height>
              <format>R8G8B8</format>
            </image>
            <clip>
              <near>0.02</near>
              <far>300</far>
            </clip>
            <noise>
              <type>gaussian</type>
              <mean>0</mean>
              <stddev>0.007</stddev>
            </noise>
          </camera>
          <plugin name='camera_controller' filename='libgazebo_ros_camera.so'>
            <alwaysOn>true</alwaysOn>
            <updateRate>0.0</updateRate>
            <cameraName>camera</cameraName>
            <imageTopicName>image_raw</imageTopicName>
            <cameraInfoTopicName>camera_info</cameraInfoTopicName>
            <frameName>camera_link</frameName>
            <hackBaseline>0.07</hackBaseline>
            <distortionK1>0.0</distortionK1>
            <distortionK2>0.0</distortionK2>
            <distortionK3>0.0</distortionK3>
            <distortionT1>0.0</distortionT1>
            <distortionT2>0.0</distortionT2>
            <robotNamespace>/</robotNamespace>
          </plugin>
          <pose frame=''>-0.1 0 -0.02 -3e-06 -1.57079 -3e-06</pose>
        </sensor>
        <self_collide>0</self_collide>
        <kinematic>0</kinematic>
      </link>
      <joint name='joint7' type='revolute'>
        <child>link7</child>
        <parent>link6</parent>
        <axis>
          <xyz>0 0 -1</xyz>
          <limit>
            <lower>-1.5708</lower>
            <upper>1.5708</upper>
            <effort>100</effort>
            <velocity>1</velocity>
          </limit>
          <dynamics>
            <spring_reference>0</spring_reference>
            <spring_stiffness>0</spring_stiffness>
          </dynamics>
          <use_parent_model_frame>1</use_parent_model_frame>
        </axis>
      </joint>
      <link name='ee_link1'>
        <pose frame=''>0 -2e-06 1.372 0 -0 0</pose>
        <inertial>
          <pose frame=''>0 0.046 0.002 0 -0 0</pose>
          <mass>0.00195</mass>
          <inertia>
            <ixx>1.50312e-07</ixx>
            <ixy>6.61485e-25</ixy>
            <ixz>1.48998e-23</ixz>
            <iyy>1.73712e-07</iyy>
            <iyz>-4.21007e-25</iyz>
            <izz>3.1525e-08</izz>
          </inertia>
        </inertial>
        <collision name='ee_link1_collision'>
          <pose frame=''>0 0 0 0 -0 0</pose>
          <geometry>
            <mesh>
              <scale>1 1 1</scale>
              <uri>/home/sdhm/catkin_ws/src/mantra_robot/mantra_with_oil_gun_description/meshes/ee_link1.STL</uri>
            </mesh>
          </geometry>
          <max_contacts>10</max_contacts>
          <surface>
            <contact>
              <ode/>
            </contact>
            <bounce/>
            <friction>
              <torsional>
                <ode/>
              </torsional>
              <ode/>
            </friction>
          </surface>
        </collision>
        <visual name='ee_link1_visual'>
          <pose frame=''>0 0 0 0 -0 0</pose>
          <geometry>
            <mesh>
              <scale>1 1 1</scale>
              <uri>/home/sdhm/catkin_ws/src/mantra_robot/mantra_with_oil_gun_description/meshes/ee_link1.STL</uri>
            </mesh>
          </geometry>
        </visual>
        <self_collide>0</self_collide>
        <kinematic>0</kinematic>
      </link>
      <joint name='ee_joint1' type='prismatic'>
        <child>ee_link1</child>
        <parent>link7</parent>
        <axis>
          <xyz>0 -1 0</xyz>
          <limit>
            <lower>0</lower>
            <upper>0.04</upper>
            <effort>0</effort>
            <velocity>0</velocity>
          </limit>
          <dynamics>
            <spring_reference>0</spring_reference>
            <spring_stiffness>0</spring_stiffness>
          </dynamics>
          <use_parent_model_frame>1</use_parent_model_frame>
        </axis>
      </joint>
      <link name='ee_link2'>
        <pose frame=''>0 -2e-06 1.372 0 -0 0</pose>
        <inertial>
          <pose frame=''>0 -0.046 0.002 0 -0 0</pose>
          <mass>0.00195</mass>
          <inertia>
            <ixx>1.50312e-07</ixx>
            <ixy>6.61485e-25</ixy>
            <ixz>1.48998e-23</ixz>
            <iyy>1.73712e-07</iyy>
            <iyz>-4.21007e-25</iyz>
            <izz>3.1525e-08</izz>
          </inertia>
        </inertial>
        <collision name='ee_link2_collision'>
          <pose frame=''>0 0 0 0 -0 0</pose>
          <geometry>
            <mesh>
              <scale>1 1 1</scale>
              <uri>/home/sdhm/catkin_ws/src/mantra_robot/mantra_with_oil_gun_description/meshes/ee_link2.STL</uri>
            </mesh>
          </geometry>
          <max_contacts>10</max_contacts>
          <surface>
            <contact>
              <ode/>
            </contact>
            <bounce/>
            <friction>
              <torsional>
                <ode/>
              </torsional>
              <ode/>
            </friction>
          </surface>
        </collision>
        <visual name='ee_link2_visual'>
          <pose frame=''>0 0 0 0 -0 0</pose>
          <geometry>
            <mesh>
              <scale>1 1 1</scale>
              <uri>/home/sdhm/catkin_ws/src/mantra_robot/mantra_with_oil_gun_description/meshes/ee_link2.STL</uri>
            </mesh>
          </geometry>
        </visual>
        <self_collide>0</self_collide>
        <kinematic>0</kinematic>
      </link>
      <joint name='ee_joint2' type='prismatic'>
        <child>ee_link2</child>
        <parent>link7</parent>
        <axis>
          <xyz>0 1 0</xyz>
          <limit>
            <lower>-0.04</lower>
            <upper>0</upper>
            <effort>0</effort>
            <velocity>0</velocity>
          </limit>
          <dynamics>
            <spring_reference>0</spring_reference>
            <spring_stiffness>0</spring_stiffness>
          </dynamics>
          <use_parent_model_frame>1</use_parent_model_frame>
        </axis>
      </joint>
      <static>0</static>
      <plugin name='gazebo_ros_control' filename='libgazebo_ros_control.so'>
        <robotNamespace>/mantra_with_oil_gun</robotNamespace>
        <legacyModeNS>true</legacyModeNS>
        <robotSimType>gazebo_ros_control/DefaultRobotHWSim</robotSimType>
      </plugin>
      <pose frame=''>0 0 0 0 -0 0</pose>
    </model>
    <state world_name='default'>
      <sim_time>86 543000000</sim_time>
      <real_time>88 256258536</real_time>
      <wall_time>1570875966 980507411</wall_time>
      <iterations>86543</iterations>
      <model name='ground_plane'>
        <pose frame=''>0 0 0 0 -0 0</pose>
        <scale>1 1 1</scale>
        <link name='link'>
          <pose frame=''>0 0 0 0 -0 0</pose>
          <velocity>0 0 0 0 -0 0</velocity>
          <acceleration>0 0 0 0 -0 0</acceleration>
          <wrench>0 0 0 0 -0 0</wrench>
        </link>
      </model>
      <model name='mantra_with_oil_gun'>
        <pose frame=''>0.000197 0.000216 0 0 -0 0.008499</pose>
        <scale>1 1 1</scale>
        <link name='base_link'>
          <pose frame=''>0.000197 0.000216 0 0 -0 0.008499</pose>
          <velocity>0 0 0.000227 -0.000668 -0.003074 0</velocity>
          <acceleration>-2.42268 -0.852869 -0.995421 -3.0309 -1.2978 -0.092795</acceleration>
          <wrench>-1211.34 -426.434 -497.711 0 -0 0</wrench>
        </link>
        <link name='ee_link1'>
          <pose frame=''>0.000146 0.000179 1.372 -1.7e-05 -4.7e-05 0.008471</pose>
          <velocity>0.001219 2.5e-05 -0.000247 0.007542 -0.020212 0.033087</velocity>
          <acceleration>-0.342942 -0.002654 0.092149 1.22989 -1.35423 1.6686</acceleration>
          <wrench>-0.000669 -5e-06 0.00018 0 -0 0</wrench>
        </link>
        <link name='ee_link2'>
          <pose frame=''>0.000146 0.000179 1.372 5.5e-05 -4.7e-05 0.008486</pose>
          <velocity>0.001219 2e-06 6.6e-05 -0.003474 -0.02032 -0.033048</velocity>
          <acceleration>-0.341355 -0.003494 0.233297 2.78445 -1.47339 -1.62675</acceleration>
          <wrench>-0.000666 -7e-06 0.000455 0 -0 0</wrench>
        </link>
        <link name='link1'>
          <pose frame=''>0.000197 0.000212 0.200501 -7e-06 2e-06 0.008484</pose>
          <velocity>0.000215 0.000385 0.000139 -0.000284 -0.00529 6.7e-05</velocity>
          <acceleration>-0.389939 0.417662 0.126589 -0.276794 0.993872 0.068691</acceleration>
          <wrench>-0.175413 0.187883 0.056945 0 -0 0</wrench>
        </link>
        <link name='link2'>
          <pose frame=''>0.000197 0.000212 0.3705 1.57081 -3.9e-05 0.008484</pose>
          <velocity>-0.000131 0.000541 0.0002 -0.001335 -0.002037 -0.001187</velocity>
          <acceleration>-0.28946 0.615234 0.251041 1.81858 -0.307748 -0.677935</acceleration>
          <wrench>-0.130213 0.276761 0.11293 0 -0 0</wrench>
        </link>
        <link name='link3'>
          <pose frame=''>0.00019 0.000206 0.540501 2.1e-05 -4e-05 0.008455</pose>
          <velocity>6.2e-05 0.00088 0.000167 -0.002061 0.001146 -0.000348</velocity>
          <acceleration>0.190963 1.09369 0.105605 -2.06174 1.15182 -0.338968</acceleration>
          <wrench>0.074968 0.429363 0.041458 0 -0 0</wrench>
        </link>
        <link name='link4'>
          <pose frame=''>0.000184 0.000202 0.700501 1.57083 -6e-05 0.008453</pose>
          <velocity>0.000436 0.001213 0.000163 -0.002144 0.002462 0.000234</velocity>
          <acceleration>0.576292 1.32902 0.229945 0.988823 0.78588 -0.566604</acceleration>
          <wrench>0.21163 0.488049 0.084442 0 -0 0</wrench>
        </link>
        <link name='link5'>
          <pose frame=''>0.000175 0.000197 0.860501 3.3e-05 -5.9e-05 0.008466</pose>
          <velocity>0.00084 0.001473 0.000192 -0.001874 0.00317 -0.000395</velocity>
          <acceleration>1.18864 1.6722 0.133498 1.26489 -0.033995 2.7562</acceleration>
          <wrench>0.436501 0.614073 0.049024 0 -0 0</wrench>
        </link>
        <link name='link6'>
          <pose frame=''>0.000165 0.000192 1.0205 1.57083 -5.4e-05 0.008464</pose>
          <velocity>0.001197 0.001697 0.000145 -0.001075 0.002369 0.001633</velocity>
          <acceleration>1.37664 1.75517 0.178427 2.0514 -0.323478 2.11654</acceleration>
          <wrench>0.505537 0.644546 0.065523 0 -0 0</wrench>
        </link>
        <link name='link7'>
          <pose frame=''>0.000153 0.000184 1.246 2.5e-05 -5.2e-05 0.008479</pose>
          <velocity>0.001796 0.001959 0.000144 0.00034 -0.000311 2.3e-05</velocity>
          <acceleration>1.8034 1.9673 0.144442 0.339687 -0.311383 0.022509</acceleration>
          <wrench>0.253284 0.276304 0.020287 0 -0 0</wrench>
        </link>
      </model>
      <light name='sun'>
        <pose frame=''>0 0 10 0 -0.8 0</pose>
      </light>
    </state>
    <gui fullscreen='0'>
      <camera name='user_camera'>
        <pose frame=''>-2.83024 -1.81762 1.1888 0 0.075643 0.452189</pose>
        <view_controller>orbit</view_controller>
        <projection_type>perspective</projection_type>
      </camera>
    </gui>
  </world>
</sdf>
