<?xml version="1.0"?>

<robot name="mantra_with_oil_gun_description" xmlns:xacro="http://ros.org/wiki/xacro">
  <xacro:property name="M_PI" value="3.1415926536" />

  <link
    name="base_link">
    <inertial>
      <origin
        xyz="5.69641035035705E-08 -7.52429850161379E-09 0.0534781808387783"
        rpy="0 0 0" />
      <mass value="5" />  <!-- modified -->
      <!-- modified -->
      <inertia  
        ixx="1.0"
        ixy="0.0"
        ixz="0.0"
        iyy="1.0"
        iyz="0.0"
        izz="1.0" />
    </inertial>
    <visual>
      <origin
        xyz="0 0 0"
        rpy="0 0 0" />
      <geometry>
        <mesh
          filename="package://mantra_with_oil_gun_description/meshes/base_link.STL" />
      </geometry>
      <material
        name="">
        <color
          rgba="1 1 1 1" />
      </material>
    </visual>
    <collision>
      <origin
        xyz="0 0 0"
        rpy="0 0 0" />
      <geometry>
        <mesh
          filename="package://mantra_with_oil_gun_description/meshes/base_link.STL" />
      </geometry>
    </collision>
  </link>
  <link
    name="link1">
    <inertial>
      <origin
        xyz="3.33697354947913E-06 0.0376725326992402 0.113954575937932"
        rpy="0 0 0" />
      <mass
        value="0.449846417611502" />
      <inertia  
        ixx="1.0"
        ixy="0.0"
        ixz="0.0"
        iyy="1.0"
        iyz="0.0"
        izz="1.0" />
    </inertial>
    <visual>
      <origin
        xyz="0 0 0"
        rpy="0 0 0" />
      <geometry>
        <mesh
          filename="package://mantra_with_oil_gun_description/meshes/link1.STL" />
      </geometry>
      <material
        name="">
        <color
          rgba="1 1 1 1" />
      </material>
    </visual>
    <collision>
      <origin
        xyz="0 0 0"
        rpy="0 0 0" />
      <geometry>
        <mesh
          filename="package://mantra_with_oil_gun_description/meshes/link1.STL" />
      </geometry>
    </collision>
  </link>
  <joint
    name="joint1"
    type="revolute">
    <origin
      xyz="0 0 0.2005"
      rpy="0 0 0" />
    <parent
      link="base_link" />
    <child
      link="link1" />
    <axis
      xyz="0 0 -1" />
    <limit
      lower="-1.5708"
      upper="1.5708"
      effort="100"
      velocity="1" />
  </joint>
  <link
    name="link2">
    <inertial>
      <origin
        xyz="3.33697354947008E-06 0.0560454240620685 0.0376725326992408"
        rpy="0 0 0" />
      <mass
        value="0.449846417611509" />
      <inertia  
        ixx="1.0"
        ixy="0.0"
        ixz="0.0"
        iyy="1.0"
        iyz="0.0"
        izz="1.0" />
    </inertial>
    <visual>
      <origin
        xyz="0 0 0"
        rpy="0 0 0" />
      <geometry>
        <mesh
          filename="package://mantra_with_oil_gun_description/meshes/link2.STL" />
      </geometry>
      <material
        name="">
        <color
          rgba="1 1 1 1" />
      </material>
    </visual>
    <collision>
      <origin
        xyz="0 0 0"
        rpy="0 0 0" />
      <geometry>
        <mesh
          filename="package://mantra_with_oil_gun_description/meshes/link2.STL" />
      </geometry>
    </collision>
  </link>
  <joint
    name="joint2"
    type="revolute">
    <origin
      xyz="0 0 0.17"
      rpy="1.5708 0 0" />
    <parent
      link="link1" />
    <child
      link="link2" />
    <axis
      xyz="0 0 -1" />
    <limit
      lower="-1.85"
      upper="1.85"
      effort="100"
      velocity="1" />
  </joint>
  <link
    name="link3">
    <inertial>
      <origin
        xyz="-7.12565212158442E-06 0.0300289146661516 0.103545651609834"
        rpy="0 0 0" />
      <mass
        value="0.392582340089193" />
      <inertia  
        ixx="1.0"
        ixy="0.0"
        ixz="0.0"
        iyy="1.0"
        iyz="0.0"
        izz="1.0" />
    </inertial>
    <visual>
      <origin
        xyz="0 0 0"
        rpy="0 0 0" />
      <geometry>
        <mesh
          filename="package://mantra_with_oil_gun_description/meshes/link3.STL" />
      </geometry>
      <material
        name="">
        <color
          rgba="1 1 1 1" />
      </material>
    </visual>
    <collision>
      <origin
        xyz="0 0 0"
        rpy="0 0 0" />
      <geometry>
        <mesh
          filename="package://mantra_with_oil_gun_description/meshes/link3.STL" />
      </geometry>
    </collision>
  </link>
  <joint
    name="joint3"
    type="revolute">
    <origin
      xyz="0 0.17 0"
      rpy="-1.5708 0 0" />
    <parent
      link="link2" />
    <child
      link="link3" />
    <axis
      xyz="0 0 -1" />
    <limit
      lower="-1.5708"
      upper="1.5708"
      effort="100"
      velocity="1" />
  </joint>
  <link
    name="link4">
    <inertial>
      <origin
        xyz="9.5043585751514E-07 0.0539665921441029 0.0317108566437211"
        rpy="0 0 0" />
      <mass
        value="0.367226253241491" />
      <inertia  
        ixx="1.0"
        ixy="0.0"
        ixz="0.0"
        iyy="1.0"
        iyz="0.0"
        izz="1.0" />
    </inertial>
    <visual>
      <origin
        xyz="0 0 0"
        rpy="0 0 0" />
      <geometry>
        <mesh
          filename="package://mantra_with_oil_gun_description/meshes/link4.STL" />
      </geometry>
      <material
        name="">
        <color
          rgba="1 1 1 1" />
      </material>
    </visual>
    <collision>
      <origin
        xyz="0 0 0"
        rpy="0 0 0" />
      <geometry>
        <mesh
          filename="package://mantra_with_oil_gun_description/meshes/link4.STL" />
      </geometry>
    </collision>
  </link>
  <joint
    name="joint4"
    type="revolute">
    <origin
      xyz="0 0 0.16"
      rpy="1.5708 0 0" />
    <parent
      link="link3" />
    <child
      link="link4" />
    <axis
      xyz="0 0 -1" />
    <limit
      lower="-1.85"
      upper="1.85"
      effort="100"
      velocity="1" />
  </joint>
  <link
    name="link5">
    <inertial>
      <origin
        xyz="9.51012096351934E-07 0.0317108567627314 0.106033406535695"
        rpy="0 0 0" />
      <mass
        value="0.367226254016741" />
      <inertia  
        ixx="1.0"
        ixy="0.0"
        ixz="0.0"
        iyy="1.0"
        iyz="0.0"
        izz="1.0" />
    </inertial>
    <visual>
      <origin
        xyz="0 0 0"
        rpy="0 0 0" />
      <geometry>
        <mesh
          filename="package://mantra_with_oil_gun_description/meshes/link5.STL" />
      </geometry>
      <material
        name="">
        <color
          rgba="1 1 1 1" />
      </material>
    </visual>
    <collision>
      <origin
        xyz="0 0 0"
        rpy="0 0 0" />
      <geometry>
        <mesh
          filename="package://mantra_with_oil_gun_description/meshes/link5.STL" />
      </geometry>
    </collision>
  </link>
  <joint
    name="joint5"
    type="revolute">
    <origin
      xyz="0 0.16 0"
      rpy="-1.5708 0 0" />
    <parent
      link="link4" />
    <child
      link="link5" />
    <axis
      xyz="0 0 -1" />
    <limit
      lower="-1.5708"
      upper="1.5708"
      effort="100"
      velocity="1" />
  </joint>
  <link
    name="link6">
    <inertial>
      <origin
        xyz="9.50435834835184E-07 0.0539665921440784 0.0317108566434664"
        rpy="0 0 0" />
      <mass
        value="0.367226253239117" />
      <inertia  
        ixx="1.0"
        ixy="0.0"
        ixz="0.0"
        iyy="1.0"
        iyz="0.0"
        izz="1.0" />
    </inertial>
    <visual>
      <origin
        xyz="0 0 0"
        rpy="0 0 0" />
      <geometry>
        <mesh
          filename="package://mantra_with_oil_gun_description/meshes/link6.STL" />
      </geometry>
      <material
        name="">
        <color
          rgba="1 1 1 1" />
      </material>
    </visual>
    <collision>
      <origin
        xyz="0 0 0"
        rpy="0 0 0" />
      <geometry>
        <mesh
          filename="package://mantra_with_oil_gun_description/meshes/link6.STL" />
      </geometry>
    </collision>
  </link>
  <joint
    name="joint6"
    type="revolute">
    <origin
      xyz="0 0 0.16"
      rpy="1.5708 0 0" />
    <parent
      link="link5" />
    <child
      link="link6" />
    <axis
      xyz="0 0 -1" />
    <limit
      lower="-1.85"
      upper="1.85"
      effort="100"
      velocity="1" />
  </joint>
  <link
    name="link7">
    <inertial>
      <origin
        xyz="7.91773891106126E-17 -1.10416395174545E-05 0.0404968347411467"
        rpy="0 0 0" />
      <mass
        value="0.14043817532843" />
      <inertia  
        ixx="1.0"
        ixy="0.0"
        ixz="0.0"
        iyy="1.0"
        iyz="0.0"
        izz="1.0" />
    </inertial>
    <visual>
      <origin
        xyz="0 0 0"
        rpy="0 0 0" />
      <geometry>
        <mesh
          filename="package://mantra_with_oil_gun_description/meshes/link7.STL" />
      </geometry>
      <material
        name="">
        <color
          rgba="1 1 1 1" />
      </material>
    </visual>
    <collision>
      <origin
        xyz="0 0 0"
        rpy="0 0 0" />
      <geometry>
        <mesh
          filename="package://mantra_with_oil_gun_description/meshes/link7.STL" />
      </geometry>
    </collision>
  </link>
  <joint
    name="joint7"
    type="revolute">
    <origin
      xyz="0 0.16 0"
      rpy="-1.5708 0 0" />
    <parent
      link="link6" />
    <child
      link="link7" />
    <axis
      xyz="0 0 -1" />
    <limit
      lower="-1.5708"
      upper="1.5708"
      effort="100"
      velocity="1" />
  </joint>
  <link
    name="oil_gun_link">
    <inertial>
      <origin
        xyz="0 0 -0.838686124360706"
        rpy="0 0 0" />
      <mass
        value="0.045959936378476" />
      <inertia  
        ixx="1.0"
        ixy="0.0"
        ixz="0.0"
        iyy="1.0"
        iyz="0.0"
        izz="1.0" />
    </inertial>
    <visual>
      <origin
        xyz="0 0 0"
        rpy="0 0 0" />
      <geometry>
        <mesh
          filename="package://mantra_with_oil_gun_description/meshes/oil_gun.STL" />
      </geometry>
      <material
        name="">
        <color
          rgba="1 1 1 1" />
      </material>
    </visual>
    <collision>
      <origin
        xyz="0 0 0"
        rpy="0 0 0" />
      <geometry>
        <mesh
          filename="package://mantra_with_oil_gun_description/meshes/oil_gun.STL" />
      </geometry>
    </collision>
  </link>
  <joint
    name="oil_gun_joint"
    type="fixed">
    <origin
      xyz="0 0 0.0655"
      rpy="1.5708 0 0" />
    <parent
      link="link7" />
    <child
      link="oil_gun_link" />
    <axis
      xyz="0 0 0" />
    <limit
      lower="-1.85"
      upper="1.85"
      effort="100"
      velocity="1" />
  </joint>

  <gazebo reference="oil_gun_link">
        <material>Gazebo/Red</material>
    </gazebo>

  <!-- scene -->
  <xacro:include filename="$(find mantra_with_oil_gun_gazebo)/urdf/scene.urdf.xacro" />

  <!-- sensors -->
  <xacro:include filename="$(find mantra_with_oil_gun_gazebo)/urdf/sensors/camera.urdf.xacro" />

  <!-- #################################  gazebo ################################## -->
  <!-- modify EffortJointInterface to PositionJointInterface -->
  <transmission name="trans_joint1">
      <type>transmission_interface/SimpleTransmission</type>
      <joint name="joint1">
          <hardwareInterface>hardware_interface/PositionJointInterface</hardwareInterface>
      </joint>
      <actuator name="joint1_motor">
          <hardwareInterface>hardware_interface/PositionJointInterface</hardwareInterface>
          <mechanicalReduction>1</mechanicalReduction>
      </actuator>
  </transmission>
  <transmission name="trans_joint2">
      <type>transmission_interface/SimpleTransmission</type>
      <joint name="joint2">
          <hardwareInterface>hardware_interface/PositionJointInterface</hardwareInterface>
      </joint>
      <actuator name="joint2_motor">
          <hardwareInterface>hardware_interface/PositionJointInterface</hardwareInterface>
          <mechanicalReduction>1</mechanicalReduction>
      </actuator>
  </transmission>
  <transmission name="trans_joint3">
      <type>transmission_interface/SimpleTransmission</type>
      <joint name="joint3">
          <hardwareInterface>hardware_interface/PositionJointInterface</hardwareInterface>
      </joint>
      <actuator name="joint3_motor">
          <hardwareInterface>hardware_interface/PositionJointInterface</hardwareInterface>
          <mechanicalReduction>1</mechanicalReduction>
      </actuator>
  </transmission>
  <transmission name="trans_joint4">
      <type>transmission_interface/SimpleTransmission</type>
      <joint name="joint4">
          <hardwareInterface>hardware_interface/PositionJointInterface</hardwareInterface>
      </joint>
      <actuator name="joint4_motor">
          <hardwareInterface>hardware_interface/PositionJointInterface</hardwareInterface>
          <mechanicalReduction>1</mechanicalReduction>
      </actuator>
  </transmission>
  <transmission name="trans_joint5">
      <type>transmission_interface/SimpleTransmission</type>
      <joint name="joint5">
          <hardwareInterface>hardware_interface/PositionJointInterface</hardwareInterface>
      </joint>
      <actuator name="joint5_motor">
          <hardwareInterface>hardware_interface/PositionJointInterface</hardwareInterface>
          <mechanicalReduction>1</mechanicalReduction>
      </actuator>
  </transmission>
  <transmission name="trans_joint6">
      <type>transmission_interface/SimpleTransmission</type>
      <joint name="joint6">
          <hardwareInterface>hardware_interface/PositionJointInterface</hardwareInterface>
      </joint>
      <actuator name="joint6_motor">
          <hardwareInterface>hardware_interface/PositionJointInterface</hardwareInterface>
          <mechanicalReduction>1</mechanicalReduction>
      </actuator>
  </transmission>
  <transmission name="trans_joint7">
      <type>transmission_interface/SimpleTransmission</type>
      <joint name="joint7">
          <hardwareInterface>hardware_interface/PositionJointInterface</hardwareInterface>
      </joint>
      <actuator name="joint7_motor">
          <hardwareInterface>hardware_interface/PositionJointInterface</hardwareInterface>
          <mechanicalReduction>1</mechanicalReduction>
      </actuator>
  </transmission>
  
  <!-- gazebo_ros_control -->
  <gazebo>
      <plugin name="gazebo_ros_control" filename="libgazebo_ros_control.so">
          <robotNamespace>/mantra_with_oil_gun</robotNamespace>  <!-- modified -->
          <legacyModeNS>true</legacyModeNS> <!-- modified -->
          <robotSimType>gazebo_ros_control/DefaultRobotHWSim</robotSimType> <!-- modified -->
      </plugin>
  </gazebo>

</robot>
