<?xml version="1.0" encoding="utf-8"?>
<!-- This URDF was automatically created by SolidWorks to URDF Exporter! Originally created by Stephen Brawner (brawner@gmail.com) 
     Commit Version: 1.5.0-0-g9aa0fdb  Build Version: 1.5.7004.21443
     For more information, please see http://wiki.ros.org/sw_urdf_exporter -->
<robot
  name="mantra">
  <link
    name="base_link">
    <!-- <inertial>
      <origin
        xyz="5.6964103503558E-08 -7.5242985015266E-09 0.0534781808387783"
        rpy="0 0 0" />
      <mass
        value="2.12515524577406" />
      <inertia
        ixx="0.00919560446596015"
        ixy="2.13793974776523E-09"
        ixz="-1.75777317027312E-09"
        iyy="0.00919559841583678"
        iyz="3.46157313091353E-10"
        izz="0.011098052703463" />
    </inertial> -->
    <visual>
      <origin
        xyz="0 0 0"
        rpy="0 0 0" />
      <geometry>
        <mesh
          filename="package://mantra_description/meshes/visual/base_link.dae" />
      </geometry>
      <material
        name="">
        <color
          rgba="0.4 0.4 0.4 1.0" />
      </material>
    </visual>
    <collision>
      <origin
        xyz="0 0 0"
        rpy="0 0 0" />
      <geometry>
        <mesh
          filename="package://mantra_description/meshes/collision/base_link.STL" />
      </geometry>
    </collision>
  </link>
  <link
    name="link1">
    <inertial>
      <origin
        xyz="3.337E-06 0.037673 0.11395"
        rpy="0 0 0" />
      <mass
        value="0.44985" />
      <inertia
        ixx="0.0028154"
        ixy="-2.9793E-08"
        ixz="2.3155E-09"
        iyy="0.0023788"
        iyz="-0.00068961"
        izz="0.0016167" />
    </inertial>
    <visual>
      <origin
        xyz="0 0 0"
        rpy="0 0 0" />
      <geometry>
        <mesh
          filename="package://mantra_description/meshes/visual/link1.dae" />
      </geometry>
      <material
        name="">
        <color
          rgba="1 0.423 0.039 1" />
      </material>
    </visual>
    <collision>
      <origin
        xyz="0 0 0"
        rpy="0 0 0" />
      <geometry>
        <mesh
          filename="package://mantra_description/meshes/collision/link1.STL" />
      </geometry>
    </collision>
  </link>
  <joint
    name="joint1"
    type="revolute">
    <origin
      xyz="0 0 0.2005"
      rpy="0 0 0" />
    <parent
      link="base_link" />
    <child
      link="link1" />
    <axis
      xyz="0 0 -1" />
    <limit
      lower="-3.0"
      upper="3.0"
      effort="0"
      velocity="0" />
  </joint>
  <link
    name="link2">
    <inertial>
      <origin
        xyz="3.337E-06 0.056045 0.037673"
        rpy="0 0 0" />
      <mass
        value="0.44985" />
      <inertia
        ixx="0.0028154"
        ixy="-2.3155E-09"
        ixz="-2.9793E-08"
        iyy="0.0016167"
        iyz="0.00068961"
        izz="0.0023788" />
    </inertial>
    <visual>
      <origin
        xyz="0 0 0"
        rpy="0 0 0" />
      <geometry>
        <mesh
          filename="package://mantra_description/meshes/visual/link2.dae" />
      </geometry>
      <material
        name="">
        <color
          rgba="1 0.423 0.039 1" />
      </material>
    </visual>
    <collision>
      <origin
        xyz="0 0 0"
        rpy="0 0 0" />
      <geometry>
        <mesh
          filename="package://mantra_description/meshes/collision/link2.STL" />
      </geometry>
    </collision>
  </link>
  <joint
    name="joint2"
    type="revolute">
    <origin
      xyz="0 0 0.17"
      rpy="1.5707963267949 0 0" />
    <parent
      link="link1" />
    <child
      link="link2" />
    <axis
      xyz="0 0 1" />
    <limit
      lower="-1.930"
      upper="1.930"
      effort="0"
      velocity="0" />
  </joint>
  <link
    name="link3">
    <inertial>
      <origin
        xyz="-7.1257E-06 0.030029 0.10355"
        rpy="0 0 0" />
      <mass
        value="0.39258" />
      <inertia
        ixx="0.0020755"
        ixy="1.3934E-08"
        ixz="-2.8548E-08"
        iyy="0.001787"
        iyz="-0.00050316"
        izz="0.0012141" />
    </inertial>
    <visual>
      <origin
        xyz="0 0 0"
        rpy="0 0 0" />
      <geometry>
        <mesh
          filename="package://mantra_description/meshes/visual/link3.dae" />
      </geometry>
      <material
        name="">
        <color
          rgba="1 0.423 0.039 1" />
      </material>
    </visual>
    <collision>
      <origin
        xyz="0 0 0"
        rpy="0 0 0" />
      <geometry>
        <mesh
          filename="package://mantra_description/meshes/collision/link3.STL" />
      </geometry>
    </collision>
  </link>
  <joint
    name="joint3"
    type="revolute">
    <origin
      xyz="0 0.17 0"
      rpy="-1.5707963267949 0 0" />
    <parent
      link="link2" />
    <child
      link="link3" />
    <axis
      xyz="0 0 -1" />
    <limit
      lower="-3.0"
      upper="3.0"
      effort="0"
      velocity="0" />
  </joint>
  <link
    name="link4">
    <inertial>
      <origin
        xyz="9.5044E-07 0.053967 0.031711"
        rpy="0 0 0" />
      <mass
        value="0.36723" />
      <inertia
        ixx="0.0018995"
        ixy="1.1076E-08"
        ixz="-3.7571E-09"
        iyy="0.0010261"
        iyz="0.00046741"
        izz="0.0016317" />
    </inertial>
    <visual>
      <origin
        xyz="0 0 0"
        rpy="0 0 0" />
      <geometry>
        <mesh
          filename="package://mantra_description/meshes/visual/link4.dae" />
      </geometry>
      <material
        name="">
        <color
          rgba="1 0.423 0.039 1" />
      </material>
    </visual>
    <collision>
      <origin
        xyz="0 0 0"
        rpy="0 0 0" />
      <geometry>
        <mesh
          filename="package://mantra_description/meshes/collision/link4.STL" />
      </geometry>
    </collision>
  </link>
  <joint
    name="joint4"
    type="revolute">
    <origin
      xyz="0 0 0.16"
      rpy="1.5707963267949 0 0" />
    <parent
      link="link3" />
    <child
      link="link4" />
    <axis
      xyz="0 0 1" />
    <limit
      lower="-1.880"
      upper="1.880"
      effort="0"
      velocity="0" />
  </joint>
  <link
    name="link5">
    <inertial>
      <origin
        xyz="9.5101E-07 0.031711 0.10603"
        rpy="0 0 0" />
      <mass
        value="0.36723" />
      <inertia
        ixx="0.0018995"
        ixy="-3.7597E-09"
        ixz="-1.1061E-08"
        iyy="0.0016317"
        iyz="-0.00046741"
        izz="0.0010261" />
    </inertial>
    <visual>
      <origin
        xyz="0 0 0"
        rpy="0 0 0" />
      <geometry>
        <mesh
          filename="package://mantra_description/meshes/visual/link5.dae" />
      </geometry>
      <material
        name="">
        <color
          rgba="1 0.423 0.039 1" />
      </material>
    </visual>
    <collision>
      <origin
        xyz="0 0 0"
        rpy="0 0 0" />
      <geometry>
        <mesh
          filename="package://mantra_description/meshes/collision/link5.STL" />
      </geometry>
    </collision>
  </link>
  <joint
    name="joint5"
    type="revolute">
    <origin
      xyz="0 0.16 0"
      rpy="-1.5707963267949 0 0" />
    <parent
      link="link4" />
    <child
      link="link5" />
    <axis
      xyz="0 0 -1" />
    <limit
      lower="-3.0"
      upper="3.0"
      effort="0"
      velocity="0" />
  </joint>
  <link
    name="link6">
    <inertial>
      <origin
        xyz="9.5044E-07 0.053967 0.031711"
        rpy="0 0 0" />
      <mass
        value="0.36723" />
      <inertia
        ixx="0.0018995"
        ixy="1.1088E-08"
        ixz="-3.815E-09"
        iyy="0.0010261"
        iyz="0.00046741"
        izz="0.0016317" />
    </inertial>
    <visual>
      <origin
        xyz="0 0 0"
        rpy="0 0 0" />
      <geometry>
        <mesh
          filename="package://mantra_description/meshes/visual/link6.dae" />
      </geometry>
      <material
        name="">
        <color
          rgba="1 0.423 0.039 1" />
      </material>
    </visual>
    <collision>
      <origin
        xyz="0 0 0"
        rpy="0 0 0" />
      <geometry>
        <mesh
          filename="package://mantra_description/meshes/collision/link6.STL" />
      </geometry>
    </collision>
  </link>
  <joint
    name="joint6"
    type="revolute">
    <origin
      xyz="0 0 0.16"
      rpy="1.5707963267949 0 0" />
    <parent
      link="link5" />
    <child
      link="link6" />
    <axis
      xyz="0 0 1" />
    <limit
      lower="-1.930"
      upper="1.930"
      effort="0"
      velocity="0" />
  </joint>
  <link
    name="link7">
    <inertial>
      <origin
        xyz="4.1204E-16 -1.1042E-05 0.040497"
        rpy="0 0 0" />
      <mass
        value="0.14044" />
      <inertia
        ixx="0.00016656"
        ixy="4.8932E-20"
        ixz="-9.6151E-20"
        iyy="0.0001666"
        iyz="2.7873E-08"
        izz="0.00023249" />
    </inertial>
    <visual>
      <origin
        xyz="0 0 0"
        rpy="0 0 0" />
      <geometry>
        <mesh
          filename="package://mantra_description/meshes/visual/link7.dae" />
      </geometry>
      <material
        name="">
        <color
          rgba="1 0.423 0.039 1" />
      </material>
    </visual>
    <collision>
      <origin
        xyz="0 0 0"
        rpy="0 0 0" />
      <geometry>
        <mesh
          filename="package://mantra_description/meshes/collision/link7.STL" />
      </geometry>
    </collision>
  </link>
  <joint
    name="joint7"
    type="revolute">
    <origin
      xyz="0 0.16 0"
      rpy="-1.5707963267949 0 0" />
    <parent
      link="link6" />
    <child
      link="link7" />
    <axis
      xyz="0 0 -1" />
    <limit
      lower="-3.5"
      upper="3.5"
      effort="0"
      velocity="0" />
  </joint>

  <!-- <link
    name="ee_link">
  </link> -->

  <link
    name="ee_link">
    <inertial>
      <origin
        xyz="-1.6239E-06 -8.3885E-06 0.073334"
        rpy="0 0 0" />
      <mass
        value="0.13129" />
      <inertia
        ixx="0.00014458"
        ixy="-8.9768E-14"
        ixz="6.329E-08"
        iyy="9.9096E-05"
        iyz="-6.0583E-08"
        izz="6.6591E-05" />
    </inertial>
    <visual>
      <origin
        xyz="0 0 0"
        rpy="0 0 0" />
      <geometry>
        <mesh
          filename="package://mantra_description/meshes/visual/ee_link.STL" />
      </geometry>
      <material
        name="">
        <color
          rgba="1 1 1 1" />
      </material>
    </visual>
    <collision>
      <origin
        xyz="0 0 0"
        rpy="0 0 0" />
      <geometry>
        <mesh
          filename="package://mantra_description/meshes/collision/ee_link.STL" />
      </geometry>
    </collision>
  </link>
  
  <joint
    name="ee_joint"
    type="fixed">
    <origin
      xyz="0 0 0.0655"
      rpy="0 0 0" />
    <parent
      link="link7" />
    <child
      link="ee_link" />
    <axis
      xyz="0 0 0" />
  </joint>
  
</robot>