<?xml version="1.0" encoding="utf-8"?>
<!-- This URDF was automatically created by SolidWorks to URDF Exporter! Originally created by Stephen Brawner (brawner@gmail.com) 
     Commit Version: 1.5.0-0-g9aa0fdb  Build Version: 1.5.7004.21443
     For more information, please see http://wiki.ros.org/sw_urdf_exporter -->
<robot
  name="mantra">
  <link
    name="base_link">
    <!-- <inertial>
      <origin
        xyz="5.696410350353E-08 -7.52429850161379E-09 0.0534781808387783"
        rpy="0 0 0" />
      <mass
        value="2.12515524577406" />
      <inertia
        ixx="0.00919560446596015"
        ixy="2.1379397477693E-09"
        ixz="-1.7577731702539E-09"
        iyy="0.00919559841583677"
        iyz="3.46157313100167E-10"
        izz="0.011098052703463" />
    </inertial> -->
    <visual>
      <origin
        xyz="0 0 0"
        rpy="0 0 0" />
      <geometry>
        <mesh
          filename="package://mantra_description/meshes/with_yinshi/base_link.STL" />
      </geometry>
      <material
        name="">
        <color
          rgba="0.4 0.4 0.4 1.0" />
      </material>
    </visual>
    <collision>
      <origin
        xyz="0 0 0"
        rpy="0 0 0" />
      <geometry>
        <mesh
          filename="package://mantra_description/meshes/with_yinshi/base_link.STL" />
      </geometry>
    </collision>
  </link>
  <link
    name="link1">
    <inertial>
      <origin
        xyz="3.33697354947914E-06 0.0376725326992402 0.113954575937932"
        rpy="0 0 0" />
      <mass
        value="0.449846417611502" />
      <inertia
        ixx="0.00281542194513947"
        ixy="-2.9792836352844E-08"
        ixz="2.31552459199506E-09"
        iyy="0.00237879024815951"
        iyz="-0.000689611051918419"
        izz="0.00161666621542504" />
    </inertial>
    <visual>
      <origin
        xyz="0 0 0"
        rpy="0 0 0" />
      <geometry>
        <mesh
          filename="package://mantra_description/meshes/with_yinshi/link1.STL" />
      </geometry>
      <material
        name="">
        <color
          rgba="1 0.423 0.039 1" />
      </material>
    </visual>
    <collision>
      <origin
        xyz="0 0 0"
        rpy="0 0 0" />
      <geometry>
        <mesh
          filename="package://mantra_description/meshes/with_yinshi/link1.STL" />
      </geometry>
    </collision>
  </link>
  <joint
    name="joint1"
    type="revolute">
    <origin
      xyz="0 0 0.2005"
      rpy="0 0 0" />
    <parent
      link="base_link" />
    <child
      link="link1" />
    <axis
      xyz="0 0 -1" />
    <limit
      lower="-3.0"
      upper="3.0"
      effort="0"
      velocity="0" />
  </joint>
  <link
    name="link2">
    <inertial>
      <origin
        xyz="3.33697354946631E-06 0.0560454240620686 0.0376725326992408"
        rpy="0 0 0" />
      <mass
        value="0.449846417611509" />
      <inertia
        ixx="0.00281542194513949"
        ixy="-2.31552459225444E-09"
        ixz="-2.97928363555763E-08"
        iyy="0.00161666621542506"
        iyz="0.000689611051918418"
        izz="0.00237879024815952" />
    </inertial>
    <visual>
      <origin
        xyz="0 0 0"
        rpy="0 0 0" />
      <geometry>
        <mesh
          filename="package://mantra_description/meshes/with_yinshi/link2.STL" />
      </geometry>
      <material
        name="">
        <color
          rgba="1 0.423 0.039 1" />
      </material>
    </visual>
    <collision>
      <origin
        xyz="0 0 0"
        rpy="0 0 0" />
      <geometry>
        <mesh
          filename="package://mantra_description/meshes/with_yinshi/link2.STL" />
      </geometry>
    </collision>
  </link>
  <joint
    name="joint2"
    type="revolute">
    <origin
      xyz="0 0 0.17"
      rpy="1.5707963267949 0 0" />
    <parent
      link="link1" />
    <child
      link="link2" />
    <axis
      xyz="0 0 1" />
    <limit
      lower="-1.930"
      upper="1.930"
      effort="0"
      velocity="0" />
  </joint>
  <link
    name="link3">
    <inertial>
      <origin
        xyz="-7.12565212158442E-06 0.0300289146661516 0.103545651609834"
        rpy="0 0 0" />
      <mass
        value="0.392582340089193" />
      <inertia
        ixx="0.0020755242879527"
        ixy="1.39339603463881E-08"
        ixz="-2.85481111340399E-08"
        iyy="0.00178702026485436"
        iyz="-0.000503155834932376"
        izz="0.00121405044233485" />
    </inertial>
    <visual>
      <origin
        xyz="0 0 0"
        rpy="0 0 0" />
      <geometry>
        <mesh
          filename="package://mantra_description/meshes/with_yinshi/link3.STL" />
      </geometry>
      <material
        name="">
        <color
          rgba="1 0.423 0.039 1" />
      </material>
    </visual>
    <collision>
      <origin
        xyz="0 0 0"
        rpy="0 0 0" />
      <geometry>
        <mesh
          filename="package://mantra_description/meshes/with_yinshi/link3.STL" />
      </geometry>
    </collision>
  </link>
  <joint
    name="joint3"
    type="revolute">
    <origin
      xyz="0 0.17 0"
      rpy="-1.5707963267949 0 0" />
    <parent
      link="link2" />
    <child
      link="link3" />
    <axis
      xyz="0 0 1" />
    <limit
      lower="-3.0"
      upper="3.0"
      effort="0"
      velocity="0" />
  </joint>
  <link
    name="link4">
    <inertial>
      <origin
        xyz="9.50435857537692E-07 0.0539665921441028 0.0317108566437211"
        rpy="0 0 0" />
      <mass
        value="0.367226253241491" />
      <inertia
        ixx="0.00189945127986856"
        ixy="1.10761786474968E-08"
        ixz="-3.75707939075128E-09"
        iyy="0.00102605162314097"
        iyz="0.000467411288512599"
        izz="0.00163165412446067" />
    </inertial>
    <visual>
      <origin
        xyz="0 0 0"
        rpy="0 0 0" />
      <geometry>
        <mesh
          filename="package://mantra_description/meshes/with_yinshi/link4.STL" />
      </geometry>
      <material
        name="">
        <color
          rgba="1 0.423 0.039 1" />
      </material>
    </visual>
    <collision>
      <origin
        xyz="0 0 0"
        rpy="0 0 0" />
      <geometry>
        <mesh
          filename="package://mantra_description/meshes/with_yinshi/link4.STL" />
      </geometry>
    </collision>
  </link>
  <joint
    name="joint4"
    type="revolute">
    <origin
      xyz="0 0 0.16"
      rpy="1.5707963267949 0 0" />
    <parent
      link="link3" />
    <child
      link="link4" />
    <axis
      xyz="0 0 1" />
    <limit
      lower="-1.880"
      upper="1.880"
      effort="0"
      velocity="0" />
  </joint>
  <link
    name="link5">
    <inertial>
      <origin
        xyz="9.51012096367506E-07 0.0317108567627314 0.0423124103053669"
        rpy="0 0 0" />
      <mass
        value="0.36722625401674" />
      <inertia
        ixx="0.00189945125870264"
        ixy="-3.75974500952446E-09"
        ixz="-1.10613008672061E-08"
        iyy="0.00163165410820963"
        iyz="-0.000467411240126133"
        izz="0.00102605163568241" />
    </inertial>
    <visual>
      <origin
        xyz="0 0 0"
        rpy="0 0 0" />
      <geometry>
        <mesh
          filename="package://mantra_description/meshes/with_yinshi/link5.STL" />
      </geometry>
      <material
        name="">
        <color
          rgba="1 0.423 0.039 1" />
      </material>
    </visual>
    <collision>
      <origin
        xyz="0 0 0"
        rpy="0 0 0" />
      <geometry>
        <mesh
          filename="package://mantra_description/meshes/with_yinshi/link5.STL" />
      </geometry>
    </collision>
  </link>
  <joint
    name="joint5"
    type="revolute">
    <origin
      xyz="0 0.223720996230328 0"
      rpy="-1.5707963267949 0 0" />
    <parent
      link="link4" />
    <child
      link="link5" />
    <axis
      xyz="0 0 -1" />
    <limit
      lower="-3.0"
      upper="3.0"
      effort="0"
      velocity="0" />
  </joint>
  <link
    name="link6">
    <inertial>
      <origin
        xyz="9.50435834836122E-07 0.0539665921440784 0.0317108566434664"
        rpy="0 0 0" />
      <mass
        value="0.367226253239117" />
      <inertia
        ixx="0.00189945137374859"
        ixy="1.10879827351796E-08"
        ixz="-3.81500844083869E-09"
        iyy="0.00102605167941246"
        iyz="0.000467411315869438"
        izz="0.00163165420801843" />
    </inertial>
    <visual>
      <origin
        xyz="0 0 0"
        rpy="0 0 0" />
      <geometry>
        <mesh
          filename="package://mantra_description/meshes/with_yinshi/link6.STL" />
      </geometry>
      <material
        name="">
        <color
          rgba="1 0.423 0.039 1" />
      </material>
    </visual>
    <collision>
      <origin
        xyz="0 0 0"
        rpy="0 0 0" />
      <geometry>
        <mesh
          filename="package://mantra_description/meshes/with_yinshi/link6.STL" />
      </geometry>
    </collision>
  </link>
  <joint
    name="joint6"
    type="revolute">
    <origin
      xyz="0 0 0.096279003769672"
      rpy="1.5707963267949 0 0" />
    <parent
      link="link5" />
    <child
      link="link6" />
    <axis
      xyz="0 0 1" />
    <limit
      lower="-1.930"
      upper="1.930"
      effort="0"
      velocity="0" />
  </joint>
  <link
    name="link7">
    <inertial>
      <origin
        xyz="-7.84611413225534E-07 -9.75972749294133E-06 0.0225101360866071"
        rpy="0 0 0" />
      <mass
        value="0.271729140017722" />
      <inertia
        ixx="0.000311144419394735"
        ixy="-8.97674537328541E-14"
        ixz="6.32901187879399E-08"
        iyy="0.000265698402244976"
        iyz="-3.27108118050336E-08"
        izz="0.000299083344602784" />
    </inertial>
    <visual>
      <origin
        xyz="0 0 0"
        rpy="0 0 0" />
      <geometry>
        <mesh
          filename="package://mantra_description/meshes/with_yinshi/link7.STL" />
      </geometry>
      <material
        name="">
        <color
          rgba="1 0.423 0.039 1" />
      </material>
    </visual>
    <collision>
      <origin
        xyz="0 0 0"
        rpy="0 0 0" />
      <geometry>
        <mesh
          filename="package://mantra_description/meshes/with_yinshi/link7.STL" />
      </geometry>
    </collision>
  </link>
  <joint
    name="joint7"
    type="revolute">
    <origin
      xyz="0 0.2255 0"
      rpy="-1.5707963267949 0 0" />
    <parent
      link="link6" />
    <child
      link="link7" />
    <axis
      xyz="0 0 -1" />
    <limit
      lower="-3.0"
      upper="3.0"
      effort="0"
      velocity="0" />
  </joint>
</robot>