<sdf version='1.6'>
  <world name='default'>
    <light name='sun' type='directional'>
      <cast_shadows>1</cast_shadows>
      <pose frame=''>0 0 10 0 -0 0</pose>
      <diffuse>0.8 0.8 0.8 1</diffuse>
      <specular>0.2 0.2 0.2 1</specular>
      <attenuation>
        <range>1000</range>
        <constant>0.9</constant>
        <linear>0.01</linear>
        <quadratic>0.001</quadratic>
      </attenuation>
      <direction>-0.5 0.1 -0.9</direction>
    </light>
    <model name='ground_plane'>
      <static>1</static>
      <link name='link'>
        <collision name='collision'>
          <geometry>
            <plane>
              <normal>0 0 1</normal>
              <size>100 100</size>
            </plane>
          </geometry>
          <surface>
            <friction>
              <ode>
                <mu>100</mu>
                <mu2>50</mu2>
              </ode>
              <torsional>
                <ode/>
              </torsional>
            </friction>
            <contact>
              <ode/>
            </contact>
            <bounce/>
          </surface>
          <max_contacts>10</max_contacts>
        </collision>
        <visual name='visual'>
          <cast_shadows>0</cast_shadows>
          <geometry>
            <plane>
              <normal>0 0 1</normal>
              <size>100 100</size>
            </plane>
          </geometry>
          <material>
            <script>
              <uri>file://media/materials/scripts/gazebo.material</uri>
              <name>Gazebo/Grey</name>
            </script>
          </material>
        </visual>
        <self_collide>0</self_collide>
        <kinematic>0</kinematic>
      </link>
    </model>
    <gravity>0 0 -9.8</gravity>
    <magnetic_field>6e-06 2.3e-05 -4.2e-05</magnetic_field>
    <atmosphere type='adiabatic'/>
    <physics name='default_physics' default='0' type='ode'>
      <max_step_size>0.001</max_step_size>
      <real_time_factor>1</real_time_factor>
      <real_time_update_rate>1000</real_time_update_rate>
    </physics>
    <scene>
      <ambient>0.4 0.4 0.4 1</ambient>
      <background>0.7 0.7 0.7 1</background>
      <shadows>1</shadows>
    </scene>
    <spherical_coordinates>
      <surface_model>EARTH_WGS84</surface_model>
      <latitude_deg>0</latitude_deg>
      <longitude_deg>0</longitude_deg>
      <elevation>0</elevation>
      <heading_deg>0</heading_deg>
    </spherical_coordinates>
    <model name='mantra'>
      <link name='base_link'>
        <pose frame=''>0 0 0 0 -0 0</pose>
        <inertial>
          <pose frame=''>0 -0 0.053478 0 -0 0</pose>
          <mass>5</mass>
          <inertia>
            <ixx>1</ixx>
            <ixy>0</ixy>
            <ixz>0</ixz>
            <iyy>1</iyy>
            <iyz>0</iyz>
            <izz>1</izz>
          </inertia>
        </inertial>
        <collision name='base_link_collision'>
          <pose frame=''>0 0 0 0 -0 0</pose>
          <geometry>
            <mesh>
              <scale>1 1 1</scale>
              <uri>/home/sdhm/catkin_ws/src/mantra_robot/mantra_description/meshes/collision/base_link.STL</uri>
            </mesh>
          </geometry>
          <max_contacts>10</max_contacts>
          <surface>
            <contact>
              <ode/>
            </contact>
            <bounce/>
            <friction>
              <torsional>
                <ode/>
              </torsional>
              <ode/>
            </friction>
          </surface>
        </collision>
        <visual name='base_link_visual'>
          <pose frame=''>0 0 0 0 -0 0</pose>
          <geometry>
            <mesh>
              <scale>1 1 1</scale>
              <uri>/home/sdhm/catkin_ws/src/mantra_robot/mantra_description/meshes/visual/base_link.dae</uri>
            </mesh>
          </geometry>
        </visual>
        <self_collide>0</self_collide>
        <kinematic>0</kinematic>
      </link>
      <link name='link1'>
        <pose frame=''>0 0 0.2005 0 -0 0</pose>
        <inertial>
          <pose frame=''>3e-06 0.037673 0.11395 0 -0 0</pose>
          <mass>0.44985</mass>
          <inertia>
            <ixx>1</ixx>
            <ixy>0</ixy>
            <ixz>0</ixz>
            <iyy>1</iyy>
            <iyz>0</iyz>
            <izz>1</izz>
          </inertia>
        </inertial>
        <collision name='link1_collision'>
          <pose frame=''>0 0 0 0 -0 0</pose>
          <geometry>
            <mesh>
              <scale>1 1 1</scale>
              <uri>/home/sdhm/catkin_ws/src/mantra_robot/mantra_description/meshes/collision/link1.STL</uri>
            </mesh>
          </geometry>
          <max_contacts>10</max_contacts>
          <surface>
            <contact>
              <ode/>
            </contact>
            <bounce/>
            <friction>
              <torsional>
                <ode/>
              </torsional>
              <ode/>
            </friction>
          </surface>
        </collision>
        <visual name='link1_visual'>
          <pose frame=''>0 0 0 0 -0 0</pose>
          <geometry>
            <mesh>
              <scale>1 1 1</scale>
              <uri>/home/sdhm/catkin_ws/src/mantra_robot/mantra_description/meshes/visual/link1.dae</uri>
            </mesh>
          </geometry>
        </visual>
        <self_collide>0</self_collide>
        <kinematic>0</kinematic>
      </link>
      <joint name='joint1' type='revolute'>
        <child>link1</child>
        <parent>base_link</parent>
        <axis>
          <xyz>0 0 -1</xyz>
          <limit>
            <lower>-3</lower>
            <upper>3</upper>
            <effort>0</effort>
            <velocity>1</velocity>
          </limit>
          <dynamics>
            <spring_reference>0</spring_reference>
            <spring_stiffness>0</spring_stiffness>
          </dynamics>
          <use_parent_model_frame>1</use_parent_model_frame>
        </axis>
      </joint>
      <link name='link2'>
        <pose frame=''>0 0 0.3705 1.5708 -0 0</pose>
        <inertial>
          <pose frame=''>3e-06 0.056045 0.037673 0 -0 0</pose>
          <mass>0.44985</mass>
          <inertia>
            <ixx>1</ixx>
            <ixy>0</ixy>
            <ixz>0</ixz>
            <iyy>1</iyy>
            <iyz>0</iyz>
            <izz>1</izz>
          </inertia>
        </inertial>
        <collision name='link2_collision'>
          <pose frame=''>0 0 0 0 -0 0</pose>
          <geometry>
            <mesh>
              <scale>1 1 1</scale>
              <uri>/home/sdhm/catkin_ws/src/mantra_robot/mantra_description/meshes/collision/link2.STL</uri>
            </mesh>
          </geometry>
          <max_contacts>10</max_contacts>
          <surface>
            <contact>
              <ode/>
            </contact>
            <bounce/>
            <friction>
              <torsional>
                <ode/>
              </torsional>
              <ode/>
            </friction>
          </surface>
        </collision>
        <visual name='link2_visual'>
          <pose frame=''>0 0 0 0 -0 0</pose>
          <geometry>
            <mesh>
              <scale>1 1 1</scale>
              <uri>/home/sdhm/catkin_ws/src/mantra_robot/mantra_description/meshes/visual/link2.dae</uri>
            </mesh>
          </geometry>
        </visual>
        <self_collide>0</self_collide>
        <kinematic>0</kinematic>
      </link>
      <joint name='joint2' type='revolute'>
        <child>link2</child>
        <parent>link1</parent>
        <axis>
          <xyz>0 -1 0</xyz>
          <limit>
            <lower>-1.93</lower>
            <upper>1.93</upper>
            <effort>0</effort>
            <velocity>1</velocity>
          </limit>
          <dynamics>
            <spring_reference>0</spring_reference>
            <spring_stiffness>0</spring_stiffness>
          </dynamics>
          <use_parent_model_frame>1</use_parent_model_frame>
        </axis>
      </joint>
      <link name='link3'>
        <pose frame=''>0 -0 0.5405 0 -0 0</pose>
        <inertial>
          <pose frame=''>-7e-06 0.030029 0.10355 0 -0 0</pose>
          <mass>0.39258</mass>
          <inertia>
            <ixx>1</ixx>
            <ixy>0</ixy>
            <ixz>0</ixz>
            <iyy>1</iyy>
            <iyz>0</iyz>
            <izz>1</izz>
          </inertia>
        </inertial>
        <collision name='link3_collision'>
          <pose frame=''>0 0 0 0 -0 0</pose>
          <geometry>
            <mesh>
              <scale>1 1 1</scale>
              <uri>/home/sdhm/catkin_ws/src/mantra_robot/mantra_description/meshes/collision/link3.STL</uri>
            </mesh>
          </geometry>
          <max_contacts>10</max_contacts>
          <surface>
            <contact>
              <ode/>
            </contact>
            <bounce/>
            <friction>
              <torsional>
                <ode/>
              </torsional>
              <ode/>
            </friction>
          </surface>
        </collision>
        <visual name='link3_visual'>
          <pose frame=''>0 0 0 0 -0 0</pose>
          <geometry>
            <mesh>
              <scale>1 1 1</scale>
              <uri>/home/sdhm/catkin_ws/src/mantra_robot/mantra_description/meshes/visual/link3.dae</uri>
            </mesh>
          </geometry>
        </visual>
        <self_collide>0</self_collide>
        <kinematic>0</kinematic>
      </link>
      <joint name='joint3' type='revolute'>
        <child>link3</child>
        <parent>link2</parent>
        <axis>
          <xyz>0 0 -1</xyz>
          <limit>
            <lower>-3</lower>
            <upper>3</upper>
            <effort>0</effort>
            <velocity>1</velocity>
          </limit>
          <dynamics>
            <spring_reference>0</spring_reference>
            <spring_stiffness>0</spring_stiffness>
          </dynamics>
          <use_parent_model_frame>1</use_parent_model_frame>
        </axis>
      </joint>
      <link name='link4'>
        <pose frame=''>0 -0 0.7005 1.5708 -0 0</pose>
        <inertial>
          <pose frame=''>1e-06 0.053967 0.031711 0 -0 0</pose>
          <mass>0.36723</mass>
          <inertia>
            <ixx>1</ixx>
            <ixy>0</ixy>
            <ixz>0</ixz>
            <iyy>1</iyy>
            <iyz>0</iyz>
            <izz>1</izz>
          </inertia>
        </inertial>
        <collision name='link4_collision'>
          <pose frame=''>0 0 0 0 -0 0</pose>
          <geometry>
            <mesh>
              <scale>1 1 1</scale>
              <uri>/home/sdhm/catkin_ws/src/mantra_robot/mantra_description/meshes/collision/link4.STL</uri>
            </mesh>
          </geometry>
          <max_contacts>10</max_contacts>
          <surface>
            <contact>
              <ode/>
            </contact>
            <bounce/>
            <friction>
              <torsional>
                <ode/>
              </torsional>
              <ode/>
            </friction>
          </surface>
        </collision>
        <visual name='link4_visual'>
          <pose frame=''>0 0 0 0 -0 0</pose>
          <geometry>
            <mesh>
              <scale>1 1 1</scale>
              <uri>/home/sdhm/catkin_ws/src/mantra_robot/mantra_description/meshes/visual/link4.dae</uri>
            </mesh>
          </geometry>
        </visual>
        <self_collide>0</self_collide>
        <kinematic>0</kinematic>
      </link>
      <joint name='joint4' type='revolute'>
        <child>link4</child>
        <parent>link3</parent>
        <axis>
          <xyz>0 -1 0</xyz>
          <limit>
            <lower>-1.88</lower>
            <upper>1.88</upper>
            <effort>0</effort>
            <velocity>1</velocity>
          </limit>
          <dynamics>
            <spring_reference>0</spring_reference>
            <spring_stiffness>0</spring_stiffness>
          </dynamics>
          <use_parent_model_frame>1</use_parent_model_frame>
        </axis>
      </joint>
      <link name='link5'>
        <pose frame=''>0 -0 0.8605 0 -0 0</pose>
        <inertial>
          <pose frame=''>1e-06 0.031711 0.10603 0 -0 0</pose>
          <mass>0.36723</mass>
          <inertia>
            <ixx>1</ixx>
            <ixy>0</ixy>
            <ixz>0</ixz>
            <iyy>1</iyy>
            <iyz>0</iyz>
            <izz>1</izz>
          </inertia>
        </inertial>
        <collision name='link5_collision'>
          <pose frame=''>0 0 0 0 -0 0</pose>
          <geometry>
            <mesh>
              <scale>1 1 1</scale>
              <uri>/home/sdhm/catkin_ws/src/mantra_robot/mantra_description/meshes/collision/link5.STL</uri>
            </mesh>
          </geometry>
          <max_contacts>10</max_contacts>
          <surface>
            <contact>
              <ode/>
            </contact>
            <bounce/>
            <friction>
              <torsional>
                <ode/>
              </torsional>
              <ode/>
            </friction>
          </surface>
        </collision>
        <visual name='link5_visual'>
          <pose frame=''>0 0 0 0 -0 0</pose>
          <geometry>
            <mesh>
              <scale>1 1 1</scale>
              <uri>/home/sdhm/catkin_ws/src/mantra_robot/mantra_description/meshes/visual/link5.dae</uri>
            </mesh>
          </geometry>
        </visual>
        <self_collide>0</self_collide>
        <kinematic>0</kinematic>
      </link>
      <joint name='joint5' type='revolute'>
        <child>link5</child>
        <parent>link4</parent>
        <axis>
          <xyz>0 0 -1</xyz>
          <limit>
            <lower>-3</lower>
            <upper>3</upper>
            <effort>0</effort>
            <velocity>1</velocity>
          </limit>
          <dynamics>
            <spring_reference>0</spring_reference>
            <spring_stiffness>0</spring_stiffness>
          </dynamics>
          <use_parent_model_frame>1</use_parent_model_frame>
        </axis>
      </joint>
      <link name='link6'>
        <pose frame=''>0 -0 1.0205 1.5708 -0 0</pose>
        <inertial>
          <pose frame=''>1e-06 0.053967 0.031711 0 -0 0</pose>
          <mass>0.36723</mass>
          <inertia>
            <ixx>1</ixx>
            <ixy>0</ixy>
            <ixz>0</ixz>
            <iyy>1</iyy>
            <iyz>0</iyz>
            <izz>1</izz>
          </inertia>
        </inertial>
        <collision name='link6_collision'>
          <pose frame=''>0 0 0 0 -0 0</pose>
          <geometry>
            <mesh>
              <scale>1 1 1</scale>
              <uri>/home/sdhm/catkin_ws/src/mantra_robot/mantra_description/meshes/collision/link6.STL</uri>
            </mesh>
          </geometry>
          <max_contacts>10</max_contacts>
          <surface>
            <contact>
              <ode/>
            </contact>
            <bounce/>
            <friction>
              <torsional>
                <ode/>
              </torsional>
              <ode/>
            </friction>
          </surface>
        </collision>
        <visual name='link6_visual'>
          <pose frame=''>0 0 0 0 -0 0</pose>
          <geometry>
            <mesh>
              <scale>1 1 1</scale>
              <uri>/home/sdhm/catkin_ws/src/mantra_robot/mantra_description/meshes/visual/link6.dae</uri>
            </mesh>
          </geometry>
        </visual>
        <self_collide>0</self_collide>
        <kinematic>0</kinematic>
      </link>
      <joint name='joint6' type='revolute'>
        <child>link6</child>
        <parent>link5</parent>
        <axis>
          <xyz>0 -1 0</xyz>
          <limit>
            <lower>-1.93</lower>
            <upper>1.93</upper>
            <effort>0</effort>
            <velocity>1</velocity>
          </limit>
          <dynamics>
            <spring_reference>0</spring_reference>
            <spring_stiffness>0</spring_stiffness>
          </dynamics>
          <use_parent_model_frame>1</use_parent_model_frame>
        </axis>
      </joint>
      <link name='link7'>
        <pose frame=''>0 -0 1.1805 0 -0 0</pose>
        <inertial>
          <pose frame=''>-3e-06 -1e-05 0.08801 0 -0 0</pose>
          <mass>0.27174</mass>
          <inertia>
            <ixx>3.00066</ixx>
            <ixy>7.12401e-12</ixy>
            <ixz>1.92285e-08</ixz>
            <iyy>3.00066</iyy>
            <iyz>-1.77072e-08</iyz>
            <izz>3</izz>
          </inertia>
        </inertial>
        <collision name='link7_collision'>
          <pose frame=''>0 0 0 0 -0 0</pose>
          <geometry>
            <mesh>
              <scale>1 1 1</scale>
              <uri>/home/sdhm/catkin_ws/src/mantra_robot/mantra_description/meshes/collision/link7.STL</uri>
            </mesh>
          </geometry>
          <max_contacts>10</max_contacts>
          <surface>
            <contact>
              <ode/>
            </contact>
            <bounce/>
            <friction>
              <torsional>
                <ode/>
              </torsional>
              <ode/>
            </friction>
          </surface>
        </collision>
        <collision name='link7_fixed_joint_lump__camera_link_collision_1'>
          <pose frame=''>-0.07 0 0.1 1.5708 -0 1.5708</pose>
          <geometry>
            <mesh>
              <scale>1 1 1</scale>
              <uri>/home/sdhm/catkin_ws/src/mantra_robot/mantra_gazebo/meshes/d435.STL</uri>
            </mesh>
          </geometry>
          <surface>
            <contact>
              <ode/>
            </contact>
            <friction>
              <ode/>
              <torsional>
                <ode/>
              </torsional>
            </friction>
            <bounce/>
          </surface>
          <max_contacts>10</max_contacts>
        </collision>
        <collision name='link7_fixed_joint_lump__ee_link_collision_2'>
          <pose frame=''>0 0 0.0655 0 -0 0</pose>
          <geometry>
            <mesh>
              <scale>1 1 1</scale>
              <uri>/home/sdhm/catkin_ws/src/mantra_robot/mantra_description/meshes/collision/ee_link.STL</uri>
            </mesh>
          </geometry>
          <max_contacts>10</max_contacts>
          <surface>
            <contact>
              <ode/>
            </contact>
            <bounce/>
            <friction>
              <torsional>
                <ode/>
              </torsional>
              <ode/>
            </friction>
          </surface>
        </collision>
        <visual name='link7_visual'>
          <pose frame=''>0 0 0 0 -0 0</pose>
          <geometry>
            <mesh>
              <scale>1 1 1</scale>
              <uri>/home/sdhm/catkin_ws/src/mantra_robot/mantra_description/meshes/visual/link7.dae</uri>
            </mesh>
          </geometry>
        </visual>
        <visual name='link7_fixed_joint_lump__camera_link_visual_1'>
          <pose frame=''>-0.07 0 0.1 1.5708 -0 1.5708</pose>
          <geometry>
            <mesh>
              <scale>1 1 1</scale>
              <uri>/home/sdhm/catkin_ws/src/mantra_robot/mantra_gazebo/meshes/d435.STL</uri>
            </mesh>
          </geometry>
          <material>
            <script>
              <uri>__default__</uri>
              <name>__default__</name>
            </script>
          </material>
        </visual>
        <visual name='link7_fixed_joint_lump__ee_link_visual_2'>
          <pose frame=''>0 0 0.0655 0 -0 0</pose>
          <geometry>
            <mesh>
              <scale>1 1 1</scale>
              <uri>/home/sdhm/catkin_ws/src/mantra_robot/mantra_description/meshes/visual/ee_link.STL</uri>
            </mesh>
          </geometry>
        </visual>
        <gravity>1</gravity>
        <velocity_decay/>
        <sensor name='camera' type='camera'>
          <update_rate>30</update_rate>
          <camera name='d435i'>
            <horizontal_fov>1.0472</horizontal_fov>
            <image>
              <width>640</width>
              <height>480</height>
              <format>R8G8B8</format>
            </image>
            <clip>
              <near>0.005</near>
              <far>1.5</far>
            </clip>
            <noise>
              <type>gaussian</type>
              <mean>0</mean>
              <stddev>0.007</stddev>
            </noise>
          </camera>
          <plugin name='camera_controller' filename='libgazebo_ros_camera.so'>
            <alwaysOn>true</alwaysOn>
            <updateRate>0.0</updateRate>
            <cameraName>camera</cameraName>
            <imageTopicName>color/image_raw</imageTopicName>
            <cameraInfoTopicName>color/camera_info</cameraInfoTopicName>
            <frameName>camera_link_optical</frameName>
            <hackBaseline>0.07</hackBaseline>
            <distortionK1>0.0</distortionK1>
            <distortionK2>0.0</distortionK2>
            <distortionK3>0.0</distortionK3>
            <distortionT1>0.0</distortionT1>
            <distortionT2>0.0</distortionT2>
            <robotNamespace>/</robotNamespace>
          </plugin>
          <pose frame=''>-0.07 0 0.1 -3e-06 -1.57079 -3e-06</pose>
        </sensor>
        <self_collide>0</self_collide>
        <kinematic>0</kinematic>
      </link>
      <joint name='joint7' type='revolute'>
        <child>link7</child>
        <parent>link6</parent>
        <axis>
          <xyz>0 0 -1</xyz>
          <limit>
            <lower>-3.5</lower>
            <upper>3.5</upper>
            <effort>0</effort>
            <velocity>1</velocity>
          </limit>
          <dynamics>
            <spring_reference>0</spring_reference>
            <spring_stiffness>0</spring_stiffness>
          </dynamics>
          <use_parent_model_frame>1</use_parent_model_frame>
        </axis>
      </joint>
      <static>0</static>
      <plugin name='gazebo_ros_control' filename='libgazebo_ros_control.so'>
        <robotNamespace>/mantra</robotNamespace>
        <legacyModeNS>true</legacyModeNS>
        <robotSimType>gazebo_ros_control/DefaultRobotHWSim</robotSimType>
      </plugin>
      <pose frame=''>0 0 0 0 -0 0</pose>
    </model>
    <light name='user_spot_light_0' type='spot'>
      <pose frame=''>0.56582 0.254309 1 0 -0 0</pose>
      <diffuse>0.5 0.5 0.5 1</diffuse>
      <specular>0.1 0.1 0.1 1</specular>
      <direction>0 0 -1</direction>
      <attenuation>
        <range>20</range>
        <constant>0.5</constant>
        <linear>0.01</linear>
        <quadratic>0.001</quadratic>
      </attenuation>
      <cast_shadows>0</cast_shadows>
      <spot>
        <inner_angle>0.6</inner_angle>
        <outer_angle>1</outer_angle>
        <falloff>1</falloff>
      </spot>
    </light>
    <light name='user_spot_light_1' type='spot'>
      <pose frame=''>0.051488 -4.60335 1 0 -0 0</pose>
      <diffuse>0.5 0.5 0.5 1</diffuse>
      <specular>0.1 0.1 0.1 1</specular>
      <direction>0 0 -1</direction>
      <attenuation>
        <range>20</range>
        <constant>0.5</constant>
        <linear>0.01</linear>
        <quadratic>0.001</quadratic>
      </attenuation>
      <cast_shadows>0</cast_shadows>
      <spot>
        <inner_angle>0.6</inner_angle>
        <outer_angle>1</outer_angle>
        <falloff>1</falloff>
      </spot>
    </light>
    <light name='user_spot_light_2' type='spot'>
      <pose frame=''>-4.55766 0.039409 1 0 -0 0</pose>
      <diffuse>0.5 0.5 0.5 1</diffuse>
      <specular>0.1 0.1 0.1 1</specular>
      <direction>0 0 -1</direction>
      <attenuation>
        <range>20</range>
        <constant>0.5</constant>
        <linear>0.01</linear>
        <quadratic>0.001</quadratic>
      </attenuation>
      <cast_shadows>0</cast_shadows>
      <spot>
        <inner_angle>0.6</inner_angle>
        <outer_angle>1</outer_angle>
        <falloff>1</falloff>
      </spot>
    </light>
    <state world_name='default'>
      <sim_time>1144 282000000</sim_time>
      <real_time>274 301006245</real_time>
      <wall_time>1608256874 952812911</wall_time>
      <iterations>272350</iterations>
      <model name='Marker1'>
        <pose frame=''>0.4 0 0 0 1.57079 0</pose>
        <scale>1 1 1</scale>
        <link name='link'>
          <pose frame=''>0.4 0 0 0 1.57079 0</pose>
          <velocity>0 0 0 0 -0 0</velocity>
          <acceleration>0 0 0 0 -0 0</acceleration>
          <wrench>0 0 0 0 -0 0</wrench>
        </link>
      </model>
      <model name='ground_plane'>
        <pose frame=''>0 0 0 0 -0 0</pose>
        <scale>1 1 1</scale>
        <link name='link'>
          <pose frame=''>0 0 0 0 -0 0</pose>
          <velocity>0 0 0 0 -0 0</velocity>
          <acceleration>0 0 0 0 -0 0</acceleration>
          <wrench>0 0 0 0 -0 0</wrench>
        </link>
      </model>
      <model name='mantra'>
        <pose frame=''>0.005421 0.00169 0 2e-06 3e-06 -0.092681</pose>
        <scale>1 1 1</scale>
        <link name='base_link'>
          <pose frame=''>0.005421 0.00169 0 2e-06 3e-06 -0.092681</pose>
          <velocity>-6e-06 -5e-06 0.009317 0.003157 0.003321 -9.3e-05</velocity>
          <acceleration>0.168854 -0.166089 19.056 0.088138 -0.362308 3.03801</acceleration>
          <wrench>0.84427 -0.830444 95.2799 0 -0 0</wrench>
        </link>
        <link name='link1'>
          <pose frame=''>0.005421 0.001689 0.2005 -3e-06 -1e-06 -2.67194</pose>
          <velocity>0.000659 -0.000637 0.009321 0.003145 0.003322 0.000857</velocity>
          <acceleration>1.06628 -0.980937 9.15901 0.003579 -0.180239 -2.28488</acceleration>
          <wrench>0.479664 -0.441275 4.12018 0 -0 0</wrench>
        </link>
        <link name='link2'>
          <pose frame=''>0.005422 0.001689 0.3705 1.57079 -1.0032 -2.67194</pose>
          <velocity>0.001219 -0.00116 0.009307 0.002242 0.005085 0.000856</velocity>
          <acceleration>1.32554 -1.20567 9.30287 2.2419 -1.19842 0.856008</acceleration>
          <wrench>0.596296 -0.54237 4.1849 0 -0 0</wrench>
        </link>
        <link name='link3'>
          <pose frame=''>0.133245 0.066562 0.461893 0.943472 -0.41309 2.32367</pose>
          <velocity>0.001624 -0.001244 0.008789 -0.000161 0.003865 -0.000859</velocity>
          <acceleration>1.94252 -1.293 8.5088 2.98087 -0.723288 2.28272</acceleration>
          <wrench>0.762593 -0.507607 3.34038 0 -0 0</wrench>
        </link>
        <link name='link4'>
          <pose frame=''>0.253549 0.127619 0.54791 -2.94426 -0.713347 0.962024</pose>
          <velocity>0.002003 -0.001322 0.008299 -0.000388 0.003162 -4.3e-05</velocity>
          <acceleration>1.90324 -1.33653 8.12979 2.75403 -0.020445 3.09855</acceleration>
          <wrench>0.698927 -0.490814 2.9855 0 -0 0</wrench>
        </link>
        <link name='link5'>
          <pose frame=''>0.393996 0.054735 0.52419 -1.97019 1.17965 -2.42151</pose>
          <velocity>0.001919 -0.001326 0.007866 0.001266 0.002303 -0.000322</velocity>
          <acceleration>1.85029 -1.32634 7.59716 -1.87539 0.838112 2.81927</acceleration>
          <wrench>0.679484 -0.48707 2.78991 0 -0 0</wrench>
        </link>
        <link name='link6'>
          <pose frame=''>0.534443 -0.018148 0.50047 -1.20801 -0.143317 2.66501</pose>
          <velocity>0.001835 -0.001333 0.007436 0.000279 0.000107 0.00058</velocity>
          <acceleration>1.85501 -1.33762 7.42763 0.279055 0.107173 0.580284</acceleration>
          <wrench>0.681215 -0.491216 2.72765 0 -0 0</wrench>
        </link>
        <link name='link7'>
          <pose frame=''>0.489412 -0.0588 0.352417 -2.86118 -0.273102 3.05776</pose>
          <velocity>0.001839 -0.001311 0.007418 9.8e-05 -5.6e-05 -1.4e-05</velocity>
          <acceleration>1.8433 -1.30241 7.41461 0.098021 -0.05614 -0.014392</acceleration>
          <wrench>0.5009 -0.353916 2.01485 0 -0 0</wrench>
        </link>
      </model>
      <light name='sun'>
        <pose frame=''>0 0 10 0 -0 0</pose>
      </light>
      <light name='user_spot_light_0'>
        <pose frame=''>6.09498 0.033685 0.55544 3.14159 1.55821 3.14159</pose>
      </light>
      <light name='user_spot_light_1'>
        <pose frame=''>-0.093685 -5.71929 1.64441 1.58813 -0 0</pose>
      </light>
      <light name='user_spot_light_2'>
        <pose frame=''>-4.55275 0.039409 0.753891 3.14159 -1.56717 3.14159</pose>
      </light>
    </state>
    <gui fullscreen='0'>
      <camera name='user_camera'>
        <pose frame=''>1.38155 -1.66549 2.16646 -0 0.835644 1.91619</pose>
        <view_controller>orbit</view_controller>
        <projection_type>perspective</projection_type>
      </camera>
    </gui>
    <model name='Marker1'>
      <static>1</static>
      <link name='link'>
        <visual name='visual'>
          <geometry>
            <mesh>
              <uri>model://marker1/meshes/Marker1.dae</uri>
              <scale>0.2 0.2 0.2</scale>
            </mesh>
          </geometry>
        </visual>
        <self_collide>0</self_collide>
        <kinematic>0</kinematic>
      </link>
      <pose frame=''>0.436522 -0.011647 0 0 -0 0</pose>
    </model>
  </world>
</sdf>
