<?xml version="1.0" encoding="utf-8"?>
<!-- This URDF was automatically created by SolidWorks to URDF Exporter! Originally created by Stephen Brawner (brawner@gmail.com)
     Commit Version: 1.5.0-0-g9aa0fdb  Build Version: 1.5.7004.21443
     For more information, please see http://wiki.ros.org/sw_urdf_exporter -->
<robot
  name="mantra_with_gripper_description">
  <link
    name="base_link">
    <!-- <inertial>
      <origin
        xyz="5.69641035035705E-08 -7.52429850161379E-09 0.0534781808387783"
        rpy="0 0 0" />
      <mass
        value="2.12515524577406" />
      <inertia
        ixx="0.00919560446596015"
        ixy="2.13793974775614E-09"
        ixz="-1.7577731702399E-09"
        iyy="0.00919559841583678"
        iyz="3.46157313086279E-10"
        izz="0.011098052703463" />
    </inertial> -->
    <visual>
      <origin
        xyz="0 0 0"
        rpy="0 0 0" />
      <geometry>
        <mesh
          filename="package://mantra_with_gripper_description/meshes/base_link.STL" />
      </geometry>
      <material
        name="">
        <color
          rgba="1 1 1 1" />
      </material>
    </visual>
    <collision>
      <origin
        xyz="0 0 0"
        rpy="0 0 0" />
      <geometry>
        <mesh
          filename="package://mantra_with_gripper_description/meshes/base_link.STL" />
      </geometry>
    </collision>
  </link>
  <link
    name="link1">
    <inertial>
      <origin
        xyz="3.33697354947913E-06 0.0376725326992402 0.113954575937932"
        rpy="0 0 0" />
      <mass
        value="0.449846417611502" />
      <inertia
        ixx="0.00281542194513947"
        ixy="-2.97928363529203E-08"
        ixz="2.31552459198658E-09"
        iyy="0.00237879024815951"
        iyz="-0.000689611051918419"
        izz="0.00161666621542504" />
    </inertial>
    <visual>
      <origin
        xyz="0 0 0"
        rpy="0 0 0" />
      <geometry>
        <mesh
          filename="package://mantra_with_gripper_description/meshes/link1.STL" />
      </geometry>
      <material
        name="">
        <color
          rgba="1 1 1 1" />
      </material>
    </visual>
    <collision>
      <origin
        xyz="0 0 0"
        rpy="0 0 0" />
      <geometry>
        <mesh
          filename="package://mantra_with_gripper_description/meshes/link1.STL" />
      </geometry>
    </collision>
  </link>
  <joint
    name="joint1"
    type="revolute">
    <origin
      xyz="0 0 0.2005"
      rpy="0 0 0" />
    <parent
      link="base_link" />
    <child
      link="link1" />
    <axis
      xyz="0 0 -1" />
    <limit
      lower="-1.5708"
      upper="1.5708"
      effort="100"
      velocity="1" />
  </joint>
  <link
    name="link2">
    <inertial>
      <origin
        xyz="3.33697354947008E-06 0.0560454240620685 0.0376725326992408"
        rpy="0 0 0" />
      <mass
        value="0.449846417611509" />
      <inertia
        ixx="0.00281542194513949"
        ixy="-2.3155245922964E-09"
        ixz="-2.97928363554505E-08"
        iyy="0.00161666621542506"
        iyz="0.000689611051918419"
        izz="0.00237879024815952" />
    </inertial>
    <visual>
      <origin
        xyz="0 0 0"
        rpy="0 0 0" />
      <geometry>
        <mesh
          filename="package://mantra_with_gripper_description/meshes/link2.STL" />
      </geometry>
      <material
        name="">
        <color
          rgba="1 1 1 1" />
      </material>
    </visual>
    <collision>
      <origin
        xyz="0 0 0"
        rpy="0 0 0" />
      <geometry>
        <mesh
          filename="package://mantra_with_gripper_description/meshes/link2.STL" />
      </geometry>
    </collision>
  </link>
  <joint
    name="joint2"
    type="revolute">
    <origin
      xyz="0 0 0.17"
      rpy="1.5708 0 0" />
    <parent
      link="link1" />
    <child
      link="link2" />
    <axis
      xyz="0 0 -1" />
    <limit
      lower="-1.85"
      upper="1.85"
      effort="100"
      velocity="1" />
  </joint>
  <link
    name="link3">
    <inertial>
      <origin
        xyz="-7.12565212158442E-06 0.0300289146661516 0.103545651609834"
        rpy="0 0 0" />
      <mass
        value="0.392582340089193" />
      <inertia
        ixx="0.0020755242879527"
        ixy="1.39339603463947E-08"
        ixz="-2.854811113402E-08"
        iyy="0.00178702026485436"
        iyz="-0.000503155834932376"
        izz="0.00121405044233485" />
    </inertial>
    <visual>
      <origin
        xyz="0 0 0"
        rpy="0 0 0" />
      <geometry>
        <mesh
          filename="package://mantra_with_gripper_description/meshes/link3.STL" />
      </geometry>
      <material
        name="">
        <color
          rgba="1 1 1 1" />
      </material>
    </visual>
    <collision>
      <origin
        xyz="0 0 0"
        rpy="0 0 0" />
      <geometry>
        <mesh
          filename="package://mantra_with_gripper_description/meshes/link3.STL" />
      </geometry>
    </collision>
  </link>
  <joint
    name="joint3"
    type="revolute">
    <origin
      xyz="0 0.17 0"
      rpy="-1.5708 0 0" />
    <parent
      link="link2" />
    <child
      link="link3" />
    <axis
      xyz="0 0 -1" />
    <limit
      lower="-1.5708"
      upper="1.5708"
      effort="100"
      velocity="1" />
  </joint>
  <link
    name="link4">
    <inertial>
      <origin
        xyz="9.5043585751514E-07 0.0539665921441029 0.0317108566437211"
        rpy="0 0 0" />
      <mass
        value="0.367226253241491" />
      <inertia
        ixx="0.00189945127986856"
        ixy="1.10761786473211E-08"
        ixz="-3.7570793904099E-09"
        iyy="0.00102605162314097"
        iyz="0.000467411288512599"
        izz="0.00163165412446067" />
    </inertial>
    <visual>
      <origin
        xyz="0 0 0"
        rpy="0 0 0" />
      <geometry>
        <mesh
          filename="package://mantra_with_gripper_description/meshes/link4.STL" />
      </geometry>
      <material
        name="">
        <color
          rgba="1 1 1 1" />
      </material>
    </visual>
    <collision>
      <origin
        xyz="0 0 0"
        rpy="0 0 0" />
      <geometry>
        <mesh
          filename="package://mantra_with_gripper_description/meshes/link4.STL" />
      </geometry>
    </collision>
  </link>
  <joint
    name="joint4"
    type="revolute">
    <origin
      xyz="0 0 0.16"
      rpy="1.5708 0 0" />
    <parent
      link="link3" />
    <child
      link="link4" />
    <axis
      xyz="0 0 -1" />
    <limit
      lower="-1.85"
      upper="1.85"
      effort="100"
      velocity="1" />
  </joint>
  <link
    name="link5">
    <inertial>
      <origin
        xyz="9.51012096351934E-07 0.0317108567627314 0.106033406535695"
        rpy="0 0 0" />
      <mass
        value="0.367226254016741" />
      <inertia
        ixx="0.00189945125870264"
        ixy="-3.75974500932253E-09"
        ixz="-1.10613008672603E-08"
        iyy="0.00163165410820963"
        iyz="-0.000467411240126133"
        izz="0.00102605163568241" />
    </inertial>
    <visual>
      <origin
        xyz="0 0 0"
        rpy="0 0 0" />
      <geometry>
        <mesh
          filename="package://mantra_with_gripper_description/meshes/link5.STL" />
      </geometry>
      <material
        name="">
        <color
          rgba="1 1 1 1" />
      </material>
    </visual>
    <collision>
      <origin
        xyz="0 0 0"
        rpy="0 0 0" />
      <geometry>
        <mesh
          filename="package://mantra_with_gripper_description/meshes/link5.STL" />
      </geometry>
    </collision>
  </link>
  <joint
    name="joint5"
    type="revolute">
    <origin
      xyz="0 0.16 0"
      rpy="-1.5708 0 0" />
    <parent
      link="link4" />
    <child
      link="link5" />
    <axis
      xyz="0 0 -1" />
    <limit
      lower="-1.5708"
      upper="1.5708"
      effort="100"
      velocity="1" />
  </joint>
  <link
    name="link6">
    <inertial>
      <origin
        xyz="9.50435834835184E-07 0.0539665921440784 0.0317108566434664"
        rpy="0 0 0" />
      <mass
        value="0.367226253239117" />
      <inertia
        ixx="0.00189945137374859"
        ixy="1.10879827352058E-08"
        ixz="-3.81500844090566E-09"
        iyy="0.00102605167941246"
        iyz="0.000467411315869438"
        izz="0.00163165420801843" />
    </inertial>
    <visual>
      <origin
        xyz="0 0 0"
        rpy="0 0 0" />
      <geometry>
        <mesh
          filename="package://mantra_with_gripper_description/meshes/link6.STL" />
      </geometry>
      <material
        name="">
        <color
          rgba="1 1 1 1" />
      </material>
    </visual>
    <collision>
      <origin
        xyz="0 0 0"
        rpy="0 0 0" />
      <geometry>
        <mesh
          filename="package://mantra_with_gripper_description/meshes/link6.STL" />
      </geometry>
    </collision>
  </link>
  <joint
    name="joint6"
    type="revolute">
    <origin
      xyz="0 0 0.16"
      rpy="1.5708 0 0" />
    <parent
      link="link5" />
    <child
      link="link6" />
    <axis
      xyz="0 0 -1" />
    <limit
      lower="-1.85"
      upper="1.85"
      effort="100"
      velocity="1" />
  </joint>
  <link
    name="link7">
    <inertial>
      <origin
        xyz="7.46099887346881E-17 -1.10416395174554E-05 -0.0250031652588534"
        rpy="0 0 0" />
      <mass
        value="0.14043817532843" />
      <inertia
        ixx="0.000166560052257127"
        ixy="2.71160607993557E-20"
        ixz="-8.59213210250315E-20"
        iyy="0.000166602712740968"
        iyz="2.78725555163462E-08"
        izz="0.000232492320290339" />
    </inertial>
    <visual>
      <origin
        xyz="0 0 0"
        rpy="0 0 0" />
      <geometry>
        <mesh
          filename="package://mantra_with_gripper_description/meshes/link7.STL" />
      </geometry>
      <material
        name="">
        <color
          rgba="1 1 1 1" />
      </material>
    </visual>
    <collision>
      <origin
        xyz="0 0 0"
        rpy="0 0 0" />
      <geometry>
        <mesh
          filename="package://mantra_with_gripper_description/meshes/link7.STL" />
      </geometry>
    </collision>
  </link>
  <joint
    name="joint7"
    type="revolute">
    <origin
      xyz="0 0.2255 0"
      rpy="-1.5708 0 0" />
    <parent
      link="link6" />
    <child
      link="link7" />
    <axis
      xyz="0 0 -1" />
    <limit
      lower="-1.5708"
      upper="1.5708"
      effort="100"
      velocity="1" />
  </joint>
  <link
    name="ee_link1">
    <inertial>
      <origin
        xyz="2.85464193978627E-17 0.046 0.002"
        rpy="0 0 0" />
      <mass
        value="0.00194999999999999" />
      <inertia
        ixx="1.50312499999997E-07"
        ixy="6.61485086202342E-25"
        ixz="1.48998375260736E-23"
        iyy="1.73712499999997E-07"
        iyz="-4.21006794862361E-25"
        izz="3.15249999999998E-08" />
    </inertial>
    <visual>
      <origin
        xyz="0 0 0"
        rpy="0 0 0" />
      <geometry>
        <mesh
          filename="package://mantra_with_gripper_description/meshes/ee_link1.STL" />
      </geometry>
      <material
        name="">
        <color
          rgba="0.752941176470588 0.752941176470588 0.752941176470588 1" />
      </material>
    </visual>
    <collision>
      <origin
        xyz="0 0 0"
        rpy="0 0 0" />
      <geometry>
        <mesh
          filename="package://mantra_with_gripper_description/meshes/ee_link1.STL" />
      </geometry>
    </collision>
  </link>
  <joint
    name="ee_joint1"
    type="prismatic">
    <origin
      xyz="0 0 0.126"
      rpy="0 0 0" />
    <parent
      link="link7" />
    <child
      link="ee_link1" />
    <axis
      xyz="0 -1 0" />
    <limit
      lower="0"
      upper="0.04"
      effort="0"
      velocity="0" />
  </joint>
  <link
    name="ee_link2">
    <inertial>
      <origin
        xyz="1.46922127701119E-17 -0.046 0.002"
        rpy="0 0 0" />
      <mass
        value="0.00194999999999999" />
      <inertia
        ixx="1.50312499999997E-07"
        ixy="6.61485086202342E-25"
        ixz="1.48998375260736E-23"
        iyy="1.73712499999997E-07"
        iyz="-4.21006794862361E-25"
        izz="3.15249999999998E-08" />
    </inertial>
    <visual>
      <origin
        xyz="0 0 0"
        rpy="0 0 0" />
      <geometry>
        <mesh
          filename="package://mantra_with_gripper_description/meshes/ee_link2.STL" />
      </geometry>
      <material
        name="">
        <color
          rgba="0.752941176470588 0.752941176470588 0.752941176470588 1" />
      </material>
    </visual>
    <collision>
      <origin
        xyz="0 0 0"
        rpy="0 0 0" />
      <geometry>
        <mesh
          filename="package://mantra_with_gripper_description/meshes/ee_link2.STL" />
      </geometry>
    </collision>
  </link>
  <joint
    name="ee_joint2"
    type="prismatic">
    <origin
      xyz="0 0 0.126"
      rpy="0 0 0" />
    <parent
      link="link7" />
    <child
      link="ee_link2" />
    <axis
      xyz="0 1 0" />
    <limit
      lower="-0.04"
      upper="0"
      effort="0"
      velocity="0" />
    <mimic
      joint="ee_joint1"
      multiplier="1"
      offset="0" />
  </joint>
</robot>
